Workbook
Name _: '[1]#REF!'!$B$186
Name _: '[2]#REF!'!$B$186
Name __PA7: '[3]SW-TEO'!#REF!
Name __PA8: '[3]SW-TEO'!#REF!
Name __PD1: '[3]SW-TEO'!#REF!
Name __PE12: '[3]SW-TEO'!#REF!
Name __PE13: '[3]SW-TEO'!#REF!
Name __PE6: '[3]SW-TEO'!#REF!
Name __PE7: '[3]SW-TEO'!#REF!
Name __PE8: '[3]SW-TEO'!#REF!
Name __PE9: '[3]SW-TEO'!#REF!
Name __PH1: '[3]SW-TEO'!#REF!
Name __PI1: '[3]SW-TEO'!#REF!
Name __PK1: '[3]SW-TEO'!#REF!
Name __PK3: '[3]SW-TEO'!#REF!
Name _PA7: '[3]SW-TEO'!#REF!
Name _PA8: '[3]SW-TEO'!#REF!
Name _PD1: '[3]SW-TEO'!#REF!
Name _PE12: '[3]SW-TEO'!#REF!
Name _PE13: '[3]SW-TEO'!#REF!
Name _PE6: '[3]SW-TEO'!#REF!
Name _PE7: '[3]SW-TEO'!#REF!
Name _PE8: '[3]SW-TEO'!#REF!
Name _PE9: '[3]SW-TEO'!#REF!
Name _PH1: '[3]SW-TEO'!#REF!
Name _PI1: '[3]SW-TEO'!#REF!
Name _PK1: '[3]SW-TEO'!#REF!
Name _PK3: '[3]SW-TEO'!#REF!
Name _Toc146509935: '[5]#REF!'!$A$19
Name _Toc146509935: '[6]#REF!'!$A$19
Name aaaaa: '[7]#REF!'!$A$1
Name aaaaa: '[8]#REF!'!$A$1
Name aiu_bottom: '[9]Financ. Overview'!#REF!
Name bd: '[1]#REF!'!$C$50
Name bd: '[2]#REF!'!$C$50
Name bdb: '[1]#REF!'!$C$51
Name bdb: '[2]#REF!'!$C$51
Name CAILIAO: '[1]#REF!'!$A$28
Name CAILIAO: '[2]#REF!'!$A$28
Name cb: '[1]#REF!'!$A$26
Name cb: '[2]#REF!'!$A$26
Name dl: '[1]#REF!'!$C$25
Name dl: '[2]#REF!'!$C$25
Name dlb: '[1]#REF!'!$C$31
Name dlb: '[2]#REF!'!$C$31
Name edline: #REF!
Name ff: '[10]#REF!'!$A$8:$A$28
Name ff: '[11]#REF!'!$A$8:$A$28
Name FRC: [12]Main!$C$9
Name fz: #REF!
Name gy: '[1]#REF!'!$C$7
Name gy: '[2]#REF!'!$C$7
Name gyb: '[1]#REF!'!$C$9
Name gyb: '[2]#REF!'!$C$9
Name gyg: '[1]#REF!'!#REF!
Name gyg: '[2]#REF!'!#REF!
Name hostfee: '[9]Financ. Overview'!$H$12
Name hraiu_bottom: '[9]Financ. Overview'!#REF!
Name hvac: '[9]Financ. Overview'!#REF!
Name HWSheet: 1

Sheet 投资估算表
A1: 附表1
A2: 投 资 估 算 表
A4: =设备!A3 -> 项目名称：XXXXXX建设项目 | G4: 单位：万元、万美元
A5: 序号 | B5: 总图编号 | C5: 费用名称 | D5: 建筑面积m2 | F5: 建筑工程费 | G5: 设备工程 | I5: 安装 工程 | J5: 其他 费用 | K5: 总计 | L5: 其中 外汇
D6: 新建 | E6: 改造 | G6: 公用设备 | H6: 工艺设备
C7: 第一部分：工程费用项目
A8: 一 | C8: 水工设施
A9: 1 | C9: 横向下水滑道(110m×195.2) | D9: 0 | F9: 23865 | K9: =SUM(F9:J9) -> 23865
A10: 2 | C10: 横移区 | D10: （40000） | F10: =-D10*0.11 -> 4400 | K10: =SUM(F10:J10) -> 4400
A11: 3 | C11: 水面产品室内船台（双柳基地） | D11: 13824 | F11: 8985.6 | G11: 898.56 | H11: =设备!H15 -> 2540 | I11: 130 | K11: =SUM(F11:J11) -> 12554.16
A12: 4 | C12: 水面产品室内船台及港口设施（海西湾基地） | D12: =240*48*2 -> 23040 | F12: =D12*0.8 -> 18432 | G12: =F12*0.1 -> 1843.2 | H12: =设备!H24 -> 23840 | I12: =H12*0.08 -> 1907.2 | K12: =SUM(F12:J12) -> 46022.4
A13: 5 | C13: 舾装码头（2个） | F13: =1050*2 -> 2100 | G13: 200 | H13: =设备!H31 -> 9032 | I13: 47 | K13: =SUM(F13:J13) -> 11379
C14: 小 计 | D14: =SUM(D9:D13) -> 36864 | E14: =SUM(E9:E11) -> 0 | F14: =SUM(F9:F13) -> 57782.6 | G14: =SUM(G9:G13) -> 2941.76 | H14: =SUM(H9:H13) -> 35412 | I14: =SUM(I9:I13) -> 2084.2 | J14: =SUM(J9:J13) -> 0 | K14: =SUM(K9:K13) -> 98220.56
A16: 二 | C16: 生产性建设项目
A17: 1 | C17: 武昌总部技改项目 | D17: 0 | H17: =设备!H54 -> 4440 | I17: =H17*0.06 -> 266.4 | K17: =SUM(F17:J17) -> 4706.4
A18: 2 | C18: 水下产品联合生产厂房 | D18: =SUM(D19:D28) -> 133920 | E18: =SUM(E19:E28) -> 0 | F18: =SUM(F19:F28) -> 44323.2 | G18: =SUM(G19:G28) -> 4432.32 | H18: =SUM(H19:H28) -> 50993.2 | I18: =SUM(I19:I28) -> 3059.592 | J18: =SUM(J19:J28) -> 0 | K18: =SUM(K19:K28) -> 102808.31
A19: 2.1 | C19: 预处理车间 | D19: =180*36 -> 6480 | F19: =D19*0.2 -> 1296 | G19: =F19*0.1 -> 129.6 | H19: =设备!H62 -> 743 | I19: =H19*0.06 -> 44.58 | K19: =SUM(F19:J19) -> 2213.18
A20: 2.2 | C20: 理料间 | D20: =180*36 -> 6480 | F20: =D20*0.2 -> 1296 | G20: =F20*0.1 -> 129.6 | H20: =设备!H70 -> 970 | I20: =H20*0.06 -> 58.2 | K20: =SUM(F20:J20) -> 2453.8
A21: 2.3 | C21: 肋骨制造车间 | D21: =144*36 -> 5184 | F21: =D21*0.2 -> 1036.8 | G21: =F21*0.1 -> 103.68 | H21: =设备!H84 -> 3015 | I21: =H21*0.06 -> 180.9 | K21: =SUM(F21:J21) -> 4336.38
A22: 2.4 | C22: 壳圈制造车间 | D22: =216*36*2 -> 15552 | F22: =D22*0.25 -> 3888 | G22: =F22*0.1 -> 388.8 | H22: =设备!H105 -> 10735 | I22: =H22*0.06 -> 644.1 | K22: =SUM(F22:J22) -> 15655.9
A23: 2.5 | C23: 耐压下料车间 | D23: =144*36 -> 5184 | F23: =D23*0.25 -> 1296 | G23: =F23*0.1 -> 129.6 | H23: =设备!H121 -> 4310 | I23: =H23*0.06 -> 258.6 | K23: =SUM(F23:J23) -> 5994.2
A24: 2.6 | C24: 非耐压下料车间 | D24: =144*36 -> 5184 | F24: =D24*0.2 -> 1036.8 | G24: =F24*0.1 -> 103.68 | H24: =设备!H136 -> 2338 | I24: =H24*0.06 -> 140.28 | K24: =SUM(F24:J24) -> 3618.76
A25: 2.7 | C25: 立装车间 | D25: =192*36*2 -> 13824 | F25: =D25*0.45 -> 6220.8 | G25: =F25*0.1 -> 622.08 | H25: =设备!H163 -> 11735.2 | I25: =H25*0.06 -> 704.112 | K25: =SUM(F25:J25) -> 19282.192
A26: 2.8 | C26: 非耐压结构件制造车间 | D26: =600*36*2 -> 43200 | F26: =D26*0.25 -> 10800 | G26: =F26*0.1 -> 1080 | H26: =设备!H180 -> 4715 | I26: =H26*0.06 -> 282.9 | K26: =SUM(F26:J26) -> 16877.9
A27: 2.9 | C27: 总段泵水车间 | D27: =168*36*2 -> 12096 | F27: =D27*0.5 -> 6048 | G27: =F27*0.1 -> 604.8 | H27: =设备!H191 -> 4866 | I27: =H27*0.06 -> 291.96 | K27: =SUM(F27:J27) -> 11810.76
A28: 2.1 | C28: 船台总装车间 | D28: =288*36*2 -> 20736 | F28: =D28*0.55 -> 11404.8 | G28: =F28*0.1 -> 1140.48 | H28: =设备!H202 -> 7566 | I28: =H28*0.06 -> 453.96 | K28: =SUM(F28:J28) -> 20565.24
A29: 3 | C29: 消声瓦联合生产厂房 | D29: =SUM(D30:D32) -> 17550 | E29: =SUM(E30:E32) -> 0 | F29: =SUM(F30:F32) -> 2826 | G29: =SUM(G30:G32) -> 282.6 | H29: =SUM(H30:H32) -> 2678.6 | I29: =SUM(I30:I32) -> 160.716 | J29: =SUM(J30:J32) -> 0 | K29: =SUM(K30:K32) -> 5947.916
A30: 3.1 | C30: 装料车间 | D30: =120*21 -> 2520 | F30: =D30*0.2 -> 504 | G30: =F30*0.1 -> 50.4 | H30: =设备!H209 -> 240 | I30: =H30*0.06 -> 14.4 | K30: =SUM(F30:J30) -> 808.8
A31: 3.2 | C31: 消声瓦敷设间 | D31: =120*(21+12+21) -> 6480 | F31: =D31*0.2 -> 1296 | G31: =F31*0.1 -> 129.6 | H31: =设备!H227 -> 1959 | I31: =H31*0.06 -> 117.54 | K31: =SUM(F31:J31) -> 3502.14
A32: 3.3 | C32: 消声瓦制造车间 | D32: =114*75 -> 8550 | F32: =D32*0.12 -> 1026 | G32: =F32*0.1 -> 102.6 | H32: =设备!H249 -> 479.6 | I32: =H32*0.06 -> 28.776 | K32: =SUM(F32:J32) -> 1636.976
A33: 4 | C33: 舾装中心 | D33: =SUM(D34:D40) -> 41904 | E33: =SUM(E34:E40) -> 0 | F33: =SUM(F34:F42) -> 17704.8 | G33: =SUM(G34:G42) -> 1770.48 | H33: =SUM(H34:H42) -> 6851 | I33: =SUM(I34:I42) -> 411.06 | K33: =SUM(K34:K42) -> 26737.34
A34: 4.1 | C34: 管装车间 | D34: =204*30 -> 6120 | F34: =D34*0.25 -> 1530 | G34: =F34*0.1 -> 153 | H34: =设备!H269 -> 941 | I34: =H34*0.06 -> 56.46 | K34: =SUM(F34:J34) -> 2680.46
A35: 4.2 | C35: 机装车间 | D35: =204*36 -> 7344 | F35: =D35*0.35 -> 2570.4 | G35: =F35*0.1 -> 257.04 | H35: =设备!H278 -> 1505 | I35: =H35*0.06 -> 90.3 | K35: =SUM(F35:J35) -> 4422.74
A36: 4.3 | C36: 单元模块制造车间 | D36: =312*36 -> 11232 | F36: =D36*0.35 -> 3931.2 | G36: =F36*0.1 -> 393.12 | H36: =设备!H282 -> 440 | I36: =H36*0.06 -> 26.4 | K36: =SUM(F36:J36) -> 4790.72
A37: 4.4 | C37: 电装调试制造间 | D37: =108*36 -> 3888 | F37: =D37*0.25 -> 972 | G37: =F37*0.1 -> 97.2 | H37: =设备!H286 -> 170 | I37: =H37*0.06 -> 10.2 | K37: =SUM(F37:J37) -> 1249.4
A38: 4.5 | C38: 蓄电池车间 | D38: =108*24 -> 2592 | F38: =D38*0.25 -> 648 | G38: =F38*0.1 -> 64.8 | H38: =设备!H295 -> 1270 | I38: =H38*0.06 -> 76.2 | K38: =SUM(F38:J38) -> 2059
A39: 4.6 | C39: 核级管路制造车间 | D39: =108*30 -> 3240 | F39: =D39*0.25 -> 810 | G39: =F39*0.1 -> 81 | H39: =设备!H310 -> 1755 | I39: =H39*0.06 -> 105.3 | K39: =SUM(F39:J39) -> 2751.3
A40: 4.7 | C40: 陆上联调中心 | D40: =312*24 -> 7488 | F40: =D40*0.25 -> 1872 | G40: =F40*0.1 -> 187.2 | H40: =设备!H315 -> 770 | I40: =H40*0.06 -> 46.2 | K40: =SUM(F40:J40) -> 2875.4
A41: 4.8 | C41: **车间 | D41: =204*24 -> 4896 | F41: =D41*0.25 -> 1224 | G41: =F41*0.1 -> 122.4 | K41: =SUM(F41:J41) -> 1346.4
A42: 4.9 | C42: 生产辅楼 | D42: =96*12*3*4 -> 13824 | F42: =D42*0.3 -> 4147.2 | G42: =F42*0.1 -> 414.72 | K42: =SUM(F42:J42) -> 4561.92
...

Sheet 设备
A2: 新 增 工 艺 设 备 表
A3: 项目名称：XXXXXX建设项目 | G3: 单位：万元、万美元
A4: 序号 | B4: 设 备 名 称 | C4: 主要技术（性能）指标 | D4: 国别 | E4: 单位 | F4: 数量 | G4: 设 备 价 格 | J4: 招标情况 | K4: 备注
G5: 单价 | H5: 合计 | I5: 其中外汇
A6: =投资估算表!A8 -> 一 | B6: =投资估算表!C8 -> 水工设施
A7: （一） | B7: 横向下水滑道
A9: （二） | B9: 横移区
A11: （三） | B11: =投资估算表!C11 -> 水面产品室内船台（双柳基地）
A12: 1 | B12: 各类焊机 | C12: 500~1000A | D12: 国产 | E12: 台 | F12: 200 | G12: 1.2 | H12: =F12*G12 -> 240
A13: 2 | B13: 桥式起重机 | C13: Gn＝150t/75t，S=46.5m，H=32m | D13: 国产 | E13: 台 | F13: 2 | G13: 650 | H13: =F13*G13 -> 1300
A14: 3 | B14: 桥式起重机 | C14: Gn＝100t/20t，S=46.5m，H=32m | D14: 国产 | E14: 台 | F14: 2 | G14: 500 | H14: =F14*G14 -> 1000
B15: 合 计 | F15: =SUM(F12:F14) -> 204 | H15: =SUM(H12:H14) -> 2540
A17: （四） | B17: =投资估算表!C12 -> 水面产品室内船台及港口设施（海西湾基地）
A18: 1 | B18: 各类焊机 | C18: 500~1000A | D18: 国产 | E18: 台 | F18: 200 | G18: 1.2 | H18: =F18*G18 -> 240
A19: 2 | B19: 桥式起重机 | C19: Gn＝200t/100t，S=46.5m，H=49m | D19: 国产 | E19: 台 | F19: 2 | G19: 800 | H19: =F19*G19 -> 1600
A20: 3 | B20: 桥式起重机 | C20: Gn＝200t/50t，S=46.5m，H=49m | D20: 国产 | E20: 台 | F20: 2 | G20: 750 | H20: =F20*G20 -> 1500
A21: 4 | B21: 门座吊 | C21: Gn＝100t | D21: 国产 | E21: 台 | F21: 1 | G21: 900 | H21: =F21*G21 -> 900
A22: 5 | B22: 港作拖轮 | C22: 5000HP | D22: 国产 | E22: 台 | F22: 2 | G22: 4900 | H22: =F22*G22 -> 9800
A23: 6 | B23: 液压模块运输车 | D23: 国产 | E23: 轴线 | F23: 280 | G23: 35 | H23: =F23*G23 -> 9800
B24: 合 计 | F24: =SUM(F18:F23) -> 487 | H24: =SUM(H18:H23) -> 23840
A26: （五） | B26: =投资估算表!C13 -> 舾装码头（2个）
A27: 1 | B27: 趸船 | C27: 120m | D27: 国产 | E27: 艘 | F27: 2 | G27: 2100 | H27: =F27*G27 -> 4200
A28: 2 | B28: 趸船 | C28: 90m | D28: 国产 | E28: 艘 | F28: 2 | G28: 1900 | H28: =F28*G28 -> 3800
A29: 3 | B29: 塔式起重机 | C29: D8039 | D29: 国产 | E29: 台 | F29: 4 | G29: 238 | H29: =F29*G29 -> 952
A30: 4 | B30: 卷扬提升系统 | D30: 国产 | E30: 套 | F30: 2 | G30: 40 | H30: =F30*G30 -> 80
B31: 合 计 | F31: =SUM(F27:F30) -> 10 | H31: =SUM(H27:H30) -> 9032
B33: 总 计 | F33: =F15+F24+F31 -> 701 | H33: =H15+H24+H31 -> 35412
A35: =投资估算表!A16 -> 二 | B35: =投资估算表!C16 -> 生产性建设项目
A36: （一） | B36: =投资估算表!C17 -> 武昌总部技改项目
A37: 1 | B37: 液压升降装置 | D37: 国产 | E37: 台 | F37: 1 | G37: 300 | H37: =F37*G37 -> 300
A38: 2 | B38: 工装液氧储罐 | C38: 20m3 | D38: 国产 | E38: 台 | F38: 1 | G38: 150 | H38: =F38*G38 -> 150
A39: 3 | B39: 工装液氧储罐 | C39: 30m3 | D39: 国产 | E39: 台 | F39: 1 | G39: 200 | H39: =F39*G39 -> 200
A40: 4 | B40: 隔振元件机械阻抗检测设备 | D40: 国产 | E40: 台 | F40: 1 | G40: 600 | H40: =F40*G40 -> 600
A41: 5 | B41: 橡胶减振器蠕变测量设备 | D41: 国产 | E41: 台 | F41: 1 | G41: 480 | H41: =F41*G41 -> 480
A42: 6 | B42: 轴系低噪声安装工艺试验台架 | C42: 补充建设 | D42: 国产 | E42: 台 | F42: 1 | G42: 700 | H42: =F42*G42 -> 700
A43: 7 | B43: 预处理设备 | D43: 国产 | E43: 台 | F43: 1 | G43: 300 | H43: =F43*G43 -> 300
A44: 8 | B44: 七星棍床 | C44: 宽4m，辊5mm～16mm | D44: 国产 | E44: 台 | F44: 1 | G44: 100 | H44: =F44*G44 -> 100
A45: 9 | B45: 十一辊校平机 | C45: 宽4m，辊5mm～16mm | D45: 国产 | E45: 台 | F45: 1 | G45: 190 | H45: =F45*G45 -> 190
A46: 10 | B46: 数控肋骨冷弯机床 | D46: 国产 | E46: 台 | F46: 1 | G46: 90 | H46: =F46*G46 -> 90
A47: 11 | B47: 数控火焰等离子切割机 | C47: 有效宽度5m，有效长度30m，最大切割厚度50mm | D47: 国产 | E47: 台 | F47: 2 | G47: 150 | H47: =F47*G47 -> 300
...

Sheet 招标表
A1: 附表3
A2: 招标基本情况表
A3: =设备!A3 -> 项目名称：XXXXXX建设项目
B4: 招标范围 | D4: 招标组织形式 | F4: 招标方式 | H4: 不采用 招标方式 | I4: 说明
B5: 全部招标 | C5: 部分招标 | D5: 自行招标 | E5: 委托招标 | F5: 公开招标 | G5: 邀请招标
A6: 一、勘察 | H6: √ | I6: 单项合同低于50万元
A7: 二、设计 | H7: √ | I7: 涉及保密
A8: 三、建筑工程 | H8: √ | I8: 单项合同低于200万元
A9: 四、安装工程 | H9: √ | I9: 单项合同低于200万元
A10: 五、监理 | H10: √ | I10: 单项合同低于50万元
A11: 六、其他材料

Sheet Sheet2
B1: =1311.8*2+12740.6+24449.9+42777.9+42707.9 -> 125299.9
B2: =B1-124985.4 -> 314.5
G4: =42707.9-B2 -> 42393.4
G14: 1250.9 | H14: =G14*3 -> 3752.7
G15: 1934 | H15: =G15 -> 1934
I16: =22257.1-4407-5687 -> 12163.1
J20: =74606-28000 -> 46606
J21: =14900.6-10296 -> 4604.6
K22: =40373-10766.2-7441 -> 22165.8
