Workbook
Name _: #REF!
Name _: #REF!
Name __bli3: #REF!
Name __bli5: #REF!
Name __bzz240: #REF!
Name __clt176: #REF!
Name __clt221: #REF!
Name __clt29: #REF!
Name __clt88: #REF!
Name __cyc272: #REF!
Name __cyy10: #REF!
Name __dhj25: #REF!
Name __dlg1: #REF!
Name __dwb100: #REF!
Name __dwb25: #REF!
Name __dwb50: #REF!
Name __dwc80: #REF!
Name __dzc40: #REF!
Name __dzc50: #REF!
Name __dzc60: #REF!
Name __dzc70: #REF!
Name __dzc80: #REF!
Name __dzj4: #REF!
Name __fmt1000: #REF!
Name __fmt350: #REF!
Name __fmt400: #REF!
Name __gbz16: #REF!
Name __gfl100: #REF!
Name __gfl15: #REF!
Name __gfl150: #REF!
Name __gfl20: #REF!
Name __gfl200: #REF!
Name __gfl25: #REF!
Name __gfl250: #REF!
Name __gfl300: #REF!
Name __gfl32: #REF!
Name __gfl350: #REF!
Name __gfl40: #REF!
Name __gfl400: #REF!
Name __gfl450: #REF!
Name __gfl50: #REF!
Name __gfl80: #REF!
Name __ggd43: #REF!
Name __gkz100: #REF!
Name __gkz20: #REF!
Name __gkz32: #REF!
Name __gkz50: #REF!
Name __gpc176: #REF!
Name __gpc221: #REF!
Name __gpc279: #REF!
Name __gyb100: #REF!
Name __gyb200: #REF!
Name __gyb30: #REF!
Name __gyb60: #REF!
Name __hlt1: #REF!
Name __hlt10: #REF!
Name __hlt11: #REF!
Name __hlt12: #REF!
Name __hlt13: #REF!
Name __hlt14: #REF!

Sheet 总概
A1: 附表1-1 | AB1: 440.832 | AD1: 440.832 | AE1: 123.5496
A2: 总 概 算 表
A3: 项目名称:武船重型工程股份有限公司双柳基地桥梁区办公楼及珠港澳大桥生产设备建设项目 | S3: 单位：万元、万美元
A4: 序 号 | B4: 总图 编号 | C4: 工程项目和费用名称 | D4: 建筑面积(m2) | F4: 建 筑 工 程 | N4: 设备工程 | Q4: 安装 工程 | R4: 其他 费用 | S4: 工具器 具及生 产家具 | T4: 合计 | U4: 外汇 额度
D5: 新建 | E5: 改造 | F5: 建筑物 | G5: 构筑物 | H5: 设备 基础 | I5: 给排水 | J5: 采暖 通风 | K5: 动力 工程 | L5: 电气 工程 | M5: 小计 | N5: 公用 设备 | O5: 工艺 设备 | P5: 小计 | T5: 合计
C6: 第一部分：工程费用项目
C7: 一、生产性项目
B8: 2601# | C8: 综合办公楼 | D8: 12222.11 | F8: =汇总表!G11 -> 4265.5875 | I8: =汇总表!E14 -> 137.63698 | J8: =汇总表!E15 -> 269.69616 | L8: =汇总表!E16 -> 274.95907 | M8: =SUM(F8:L8) -> 4947.8797 | N8: =公用设备表!G56 -> 650.23 | P8: =SUM(N8:O8) -> 650.23 | T8: =SUM(M8,P8,Q8,R8) -> 5598.1097 | V8: =SUM(#REF!,#REF!,#REF!) -> #REF! | W8: =SUM(#REF!,#REF!,#REF!) -> #REF! | X8: =SUM(#REF!,#REF!,#REF!) -> #REF! | Y8: =SUM(#REF!,#REF!,#REF!) -> #REF! | Z8: =SUM(#REF!,#REF!,#REF!) -> #REF! | AA8: =SUM(#REF!,#REF!,#REF!) -> #REF! | AB8: =(M8-G8)/D8 -> 0.40483024 | AC8: =T8/D8 -> 0.45803136
C9: 珠港澳大桥生产设备 | H9: =工艺设备!K95 -> 158.778 | M9: =SUM(F9:L9) -> 158.778 | O9: =工艺设备!H95 -> 10027.155 | P9: =SUM(N9:O9) -> 10027.155 | Q9: =工艺设备!J95 -> 77.7795 | T9: =SUM(M9,P9,Q9,R9) -> 10263.713
M10: =SUM(F10:L10) -> 0 | P10: =SUM(N10:O10) -> 0 | T10: =SUM(M10,P10,Q10,R10) -> 0
C11: 小 计 | D11: =SUM(D8:D10) -> 12222.11 | E11: =SUM(E8:E10) -> 0 | F11: =SUM(F8:F10) -> 4265.5875 | G11: =SUM(G8:G10) -> 0 | H11: =SUM(H8:H10) -> 158.778 | I11: =SUM(I8:I10) -> 137.63698 | J11: =SUM(J8:J10) -> 269.69616 | K11: =SUM(K8:K10) -> 0 | ... T11: =SUM(T8:T10) -> 15861.822 | U11: =U8 -> 0 | V11: =SUM(V8:V8) -> #REF! | W11: =SUM(W8:W8) -> #REF! | X11: =SUM(X8:X8) -> #REF! | Y11: =SUM(Y8:Y8) -> #REF! | Z11: =SUM(Z8:Z8) -> #REF! | AA11: =SUM(AA8:AA8) -> #REF!
C13: 二、总图设施项目 | T13: =SUM(M13,P13,Q13) -> 0
A14: 1 | C14: 道路、广场 | F14: =3944*260/10000 -> 102.544 | M14: =SUM(F14:L14) -> 102.544 | T14: =SUM(M14,P14,Q14) -> 102.544
A15: 2 | C15: 绿化 | F15: =3046*100/10000 -> 30.46 | M15: =SUM(F15:L15) -> 30.46 | T15: =SUM(M15,P15,Q15) -> 30.46
A16: 3 | C16: 室外给排水工程 | I16: =外水费!G31/10000 -> 35.454305 | M16: =SUM(F16:L16) -> 35.454305 | T16: =SUM(M16,P16,Q16) -> 35.454305
A17: 4 | C17: 室外电气工程 | L17: =外电费!G31/10000 -> 29.011947 | M17: =SUM(F17:L17) -> 29.011947 | T17: =SUM(M17,P17,Q17) -> 29.011947
C19: 小 计 | D19: =SUM(D14:D18) -> 0 | E19: =SUM(E14:E18) -> 0 | F19: =SUM(F14:F18) -> 133.004 | G19: =SUM(G14:G18) -> 0 | H19: =SUM(H14:H18) -> 0 | I19: =SUM(I14:I18) -> 35.454305 | J19: =SUM(J14:J18) -> 0 | K19: =SUM(K14:K18) -> 0 | ... N19: =SUM(N14:N18) -> 0 | P19: =SUM(P14:P18) -> 0 | T19: =SUM(T14:T18) -> 197.47025
C21: 第一部分合计 | D21: =D19+D11 -> 12222.11 | E21: =E19+E11 -> 0 | F21: =F19+F11 -> 4398.5915 | G21: =G19+G11 -> 0 | H21: =H19+H11 -> 158.778 | I21: =I19+I11 -> 173.09128 | J21: =J19+J11 -> 269.69616 | K21: =K19+K11 -> 0 | ... U21: =U19+U11 -> 0 | V21: =SUM(V11,V19,#REF!) -> #REF! | W21: =SUM(W11,W19,#REF!) -> #REF! | X21: =SUM(X11,X19,#REF!) -> #REF! | Y21: =SUM(Y11,Y19,#REF!) -> #REF! | Z21: =SUM(Z11,Z19,#REF!) -> #REF! | AA21: =SUM(AA11,AA19,#REF!) -> #REF! | AC21: =SUM(F21,H21,I21,J21,K21,L21,N21,O21,Q21,R21,S21) -> 16059.292
C23: 第二部分：其他费用
A24: 1 | C24: =其他!B7 -> 建设单位管理费 | R24: =其他!G7 -> 175.4 | T24: =R24 -> 175.4
A25: 2 | C25: =其他!B8 -> 前期工作费 | R25: =其他!G8 -> 75.405 | T25: =R25 -> 75.405
A26: 3 | C26: =其他!B9 -> 工程建设监理费 | R26: =其他!G9 -> 128.46361 | T26: =R26 -> 128.46361
A27: 4 | C27: =其他!B10 -> 工程设计费 | R27: =其他!G10 -> 358.92541 | T27: =R27 -> 358.92541 | AB27: =M21+Q21 -> 5381.9074 | AC27: =M45+N45+Q45 -> 6032.1374
A28: 5 | C28: =其他!B11 -> 施工图审查费 | R28: =其他!G11 -> 17.94627 | T28: =R28 -> 17.94627 | AB28: =M45+Q45+N45 -> 6032.1374
A29: 6 | C29: =其他!B12 -> 工程勘察费 | R29: =其他!G12 -> 18.333165 | T29: =R29 -> 18.333165
A30: 7 | C30: =其他!B13 -> 招标代理服务费 | R30: =其他!G13 -> 79 | T30: =R30 -> 79
A31: 8 | C31: =其他!B14 -> 环境评价收费 | R31: =其他!G14 -> 16.641176 | T31: =R31 -> 16.641176
A32: 9 | C32: =其他!B15 -> 劳动安全卫生评价费 | R32: =其他!G15 -> 22.4 | T32: =R32 -> 22.4
C33: 第二部分小计 | R33: =SUM(R24:R32) -> 892.51463 | T33: =R33 -> 892.51463
C35: 第一、二部分合计 | D35: =D33+D21 -> 12222.11 | E35: =E33+E21 -> 0 | F35: =F33+F21 -> 4398.5915 | G35: =G33+G21 -> 0 | H35: =H33+H21 -> 158.778 | I35: =I33+I21 -> 173.09128 | J35: =J33+J21 -> 269.69616 | K35: =K33+K21 -> 0 | ... T35: =T33+T21 -> 16951.807 | U35: =SUM(U21,U33) -> 0 | V35: =SUM(V21,V33) -> #REF! | W35: =SUM(W21,W33) -> #REF! | X35: =SUM(X21,X33) -> #REF! | Y35: =SUM(Y21,Y33) -> #REF! | Z35: =SUM(Z21,Z33) -> #REF! | AA35: =SUM(AA21,AA33) -> #REF!
C37: 第三部分：基本预备费 | R37: =(T35)*5%+0.612155334416457 -> 848.20251 | T37: =R37 -> 848.20251
C39: 第四部分：动态投资
A40: 1 | C40: 综合预备费(动态预备费)
A41: 2 | C41: 建设期贷款利息 | R41: 0 | T41: =R41 -> 0
A42: 3 | C42: 固定资产投资方向调节税
C43: 动态投资合计 | R43: =SUM(R40:R42) -> 0 | T43: =SUM(T40:T42) -> 0
C45: 建设项目总投资 | D45: =D37+D35 -> 12222.11 | E45: =E37+E35 -> 0 | F45: =F37+F35 -> 4398.5915 | G45: =G37+G35 -> 0 | H45: =H37+H35 -> 158.778 | I45: =I37+I35 -> 173.09128 | J45: =J37+J35 -> 269.69616 | K45: =K37+K35 -> 0 | ... T45: =T37+T35 -> 17800.01 | U45: =U37+U35+U21 -> 0
T47: 17800 | U47: 0.14790845
B48: 序号 | C48: 工程费名称 | D48: 投资额 (万元) | E48: 占投资数（%） | F48: 其中外汇（万美元） | S48: 0.61215533 | T48: =T47-T45 -> -0.0095807972 | AB48: =T33/T21 -> 0.055576211
B49: 1 | C49: 建筑工程费 | D49: =M45 -> 5304.1279 | E49: =D49/$D$54 -> 0.29798456
...

Sheet 其他
A1: 附表1-2
A2: 其它费用估算表
A4: 序号 | B4: 工程或费用名称 | C4: 收费依据 | D4: 单位 | E4: 单位指标 | F4: 计算基数 | G4: 投资 （万元）
A6: 一 | B6: 其他费用 | G6: =SUM(G7:G10,G11:G16) -> 892.51463
A7: 1 | B7: 建设单位管理费 | C7: 财建[2002]394号文 | D7: 万元 | F7: =总概!T47 -> 17800 | G7: =113+(F7-10000)*0.8% -> 175.4
A8: 2 | B8: 前期工作费 | C8: 计价格[1999]1283号文 | D8: 万元 | E8: 插入法 | F8: =F7 -> 17800 | G8: =(60+(F8-10000)*(139-60)/40000) -> 75.405
A9: 3 | B9: 工程建设监理费 | C9: 发改价格[2007]670号文 | D9: 万元 | E9: 插入法 | F9: =总概!M45+总概!Q45 -> 5381.9074 | G9: =(120.8+(F9-5000)*(181-120.8)/3000) -> 128.46361
A10: 4 | B10: 工程设计费 | C10: 计价格[2002]10号文 | D10: 万元 | E10: 插入法 | F10: =总概!T21 -> 16059.292 | G10: =(304.8+(F10-10000)*(566.8-304.8)/10000)*35%*1.15*1.25+(163.9+(H10-5000)*(249.6-163.9)/3000)*65% -> 358.92541 | H10: =总概!M45+总概!Q45+总概!N45 -> 6032.1374
A11: 5 | B11: 施工图审查费 | C11: 发改价格[2011]534号文 | D11: 万元 | E11: 0.05 | F11: =G10 -> 358.92541 | G11: =F11*E11 -> 17.94627
A12: 6 | B12: 工程勘察费 | C12: 计价格[2002]10号文 | D12: 万元 | E12: 15元/m2 | F12: =总概!D45 -> 12222.11 | G12: =F12*15/10000 -> 18.333165 | H12: 工程 | I12: 公用设备 | J12: 工艺设备
A13: 7 | B13: 招标代理服务费 | C13: 计价格[2002]1980号文 | D13: 万元 | G13: 79 | H13: =[18]估算表!F27 -> 24171.334 | I13: =[18]估算表!G27 -> 3057.035
A14: 8 | B14: 环境评价收费 | C14: 计价格[2002]125号文 | D14: 万元 | F14: =F7 -> 17800 | G14: =7.5+(F14-3000)*(18-7.5)/(20000-3000) -> 16.641176
A15: 9 | B15: 劳动安全卫生评价费 | C15: 地方有关规定 | D15: 万元 | G15: 22.4
A18: 二 | B18: 基本预备费 | C18: 科工法［2005］496号 | E18: =G18/F18 -> 0.050036112 | F18: =总概!T35 -> 16951.807 | G18: =总概!T37 -> 848.20251
B20: 合计 | G20: =SUM(G6,G18:G18) -> 1740.7171

Sheet 工艺设备
A1: 附表1-3
A2: 工艺设备明细及概算表
A4: 序号 | B4: 设备名称 | C4: 设 备 购 置 费 | J4: 安装 调试费 | K4: 设备 基础费 | L4: 备注
C5: 设备价格(万元、万美元) | E5: 关税 增值税 | F5: 进口 费用 | G5: 国内 运杂费 | H5: 合价 | I5: 其中： 外币
C6: 共计 | D6: 其中外汇
A7: =新增工艺设备!A6 -> 一 | B7: =新增工艺设备!B6 -> 板单元生产线 | C7: =新增工艺设备!H6 -> 0 | D7: =新增工艺设备!I6 -> 0
A8: =新增工艺设备!A7 -> （一） | B8: =新增工艺设备!B7 -> 钢材预处理生产线 | C8: =新增工艺设备!H7 -> 0 | D8: =新增工艺设备!I7 -> 0 | H8: =C8+E8+F8+G8 -> 0
A9: =新增工艺设备!A8 -> 1.1 | B9: =新增工艺设备!B8 -> 钢板矫平机 | C9: =新增工艺设备!H8 -> 993.6 | D9: =新增工艺设备!I8 -> 0 | G9: =C9*6% -> 59.616 | H9: =C9+E9+F9+G9 -> 1053.216 | K9: =C9*3% -> 29.808
A10: =新增工艺设备!A9 -> （二） | B10: =新增工艺设备!B9 -> 下料切割生产线 | C10: =新增工艺设备!H9 -> 0 | D10: =新增工艺设备!I9 -> 0 | H10: =C10+E10+F10+G10 -> 0
A11: =新增工艺设备!A10 -> 1 | B11: =新增工艺设备!B10 -> 数控等离子切割机 | C11: =新增工艺设备!H10 -> 92.2 | D11: =新增工艺设备!I10 -> 0 | G11: =C11*6% -> 5.532 | H11: =C11+E11+F11+G11 -> 97.732 | K11: =C11*3% -> 2.766
A12: =新增工艺设备!A11 -> 2 | B12: =新增工艺设备!B11 -> 数控火焰切割机 | C12: =新增工艺设备!H11 -> 95.6 | D12: =新增工艺设备!I11 -> 0 | G12: =C12*6% -> 5.736 | H12: =C12+E12+F12+G12 -> 101.336 | K12: =C12*3% -> 2.868
A13: =新增工艺设备!A12 -> 3 | B13: =新增工艺设备!B12 -> 门式多头火焰切割机 | C13: =新增工艺设备!H12 -> 103.5 | D13: =新增工艺设备!I12 -> 0 | G13: =C13*6% -> 6.21 | H13: =C13+E13+F13+G13 -> 109.71 | K13: =C13*3% -> 3.105
A14: =新增工艺设备!A13 -> 4 | B14: =新增工艺设备!B13 -> 数控划线号料机 | C14: =新增工艺设备!H13 -> 98.6 | D14: =新增工艺设备!I13 -> 0 | G14: =C14*6% -> 5.916 | H14: =C14+E14+F14+G14 -> 104.516 | K14: =C14*3% -> 2.958
A15: =新增工艺设备!A14 -> （三） | B15: =新增工艺设备!B14 -> U肋生产线 | C15: =新增工艺设备!H14 -> 0 | D15: =新增工艺设备!I14 -> 0 | H15: =C15+E15+F15+G15 -> 0
A16: =新增工艺设备!A15 -> 1 | B16: =新增工艺设备!B15 -> 坡口铣边机 | C16: =新增工艺设备!H15 -> 240 | D16: =新增工艺设备!I15 -> 0 | G16: =C16*6% -> 14.4 | H16: =C16+E16+F16+G16 -> 254.4 | K16: =C16*3% -> 7.2
A17: =新增工艺设备!A16 -> 2 | B17: =新增工艺设备!B16 -> 双头坡口铣边机 | C17: =新增工艺设备!H16 -> 70 | D17: =新增工艺设备!I16 -> 0 | G17: =C17*6% -> 4.2 | H17: =C17+E17+F17+G17 -> 74.2 | K17: =C17*3% -> 2.1
A18: =新增工艺设备!A17 -> 3 | B18: =新增工艺设备!B17 -> R2倒角机 | C18: =新增工艺设备!H17 -> 40 | D18: =新增工艺设备!I17 -> 0 | G18: =C18*6% -> 2.4 | H18: =C18+E18+F18+G18 -> 42.4 | K18: =C18*3% -> 1.2
A19: =新增工艺设备!A18 -> 4 | B19: =新增工艺设备!B18 -> U肋板矫平机 | C19: =新增工艺设备!H18 -> 90 | D19: =新增工艺设备!I18 -> 0 | G19: =C19*6% -> 5.4 | H19: =C19+E19+F19+G19 -> 95.4 | K19: =C19*3% -> 2.7
A20: =新增工艺设备!A19 -> 5 | B20: =新增工艺设备!B19 -> 数控多边坡口成型机 | C20: =新增工艺设备!H19 -> 372 | D20: =新增工艺设备!I19 -> 0 | G20: =C20*6% -> 22.32 | H20: =C20+E20+F20+G20 -> 394.32 | J20: =C20*8% -> 29.76
A21: =新增工艺设备!A20 -> 6 | B21: =新增工艺设备!B20 -> 双台联动电液伺服数控折弯机 | C21: =新增工艺设备!H20 -> 404.5 | D21: =新增工艺设备!I20 -> 0 | G21: =C21*6% -> 24.27 | H21: =C21+E21+F21+G21 -> 428.77
A22: =新增工艺设备!A21 -> （四） | B22: =新增工艺设备!B21 -> U肋板单元生产线 | C22: =新增工艺设备!H21 -> 0 | D22: =新增工艺设备!I21 -> 0 | H22: =C22+E22+F22+G22 -> 0
A23: =新增工艺设备!A22 -> 1 | B23: =新增工艺设备!B22 -> U肋端口栓孔定位装置 | C23: =新增工艺设备!H22 -> 55.9 | D23: =新增工艺设备!I22 -> 0 | G23: =C23*6% -> 3.354 | H23: =C23+E23+F23+G23 -> 59.254
A24: =新增工艺设备!A23 -> 2 | B24: =新增工艺设备!B23 -> 移动式U肋装配机 | C24: =新增工艺设备!H23 -> 222.4 | D24: =新增工艺设备!I23 -> 0 | G24: =C24*6% -> 13.344 | H24: =C24+E24+F24+G24 -> 235.744
A25: =新增工艺设备!A24 -> 3 | B25: =新增工艺设备!B24 -> U肋龙门焊接系统 | C25: =SUM(C26:C27) -> 838.7 | D25: =SUM(D26:D27) -> 0 | E25: =SUM(E26:E27) -> 0 | F25: =SUM(F26:F27) -> 0 | G25: =SUM(G26:G27) -> 50.322 | H25: =SUM(H26:H27) -> 889.022 | I25: =SUM(I26:I27) -> 0 | J25: =SUM(J26:J27) -> 0 | ... L25: =SUM(L26:L27) -> 0
A26: =新增工艺设备!A25 -> 1 | B26: =新增工艺设备!B25 -> U肋龙门焊接机 | C26: =新增工艺设备!H25 -> 718.7 | D26: =新增工艺设备!I25 -> 0 | G26: =C26*6% -> 43.122 | H26: =C26+E26+F26+G26 -> 761.822 | K26: =C26*3% -> 21.561
A27: =新增工艺设备!A26 -> 2 | B27: =新增工艺设备!B26 -> 逆变埋弧自动焊机 | C27: =新增工艺设备!H26 -> 120 | D27: =新增工艺设备!I26 -> 0 | G27: =C27*6% -> 7.2 | H27: =C27+E27+F27+G27 -> 127.2 | K27: =C27*3% -> 3.6
A28: =新增工艺设备!A27 -> 4 | B28: =新增工艺设备!B27 -> U肋板单元机械滚压矫正机 | C28: =新增工艺设备!H27 -> 417.9 | D28: =新增工艺设备!I27 -> 0 | G28: =C28*6% -> 25.074 | H28: =C28+E28+F28+G28 -> 442.974 | K28: =C28*3% -> 12.537
A29: =新增工艺设备!A28 -> 5 | B29: =新增工艺设备!B28 -> 底板对齐装配胎架 | C29: =新增工艺设备!H28 -> 78.8 | D29: =新增工艺设备!I28 -> 0 | G29: =C29*6% -> 4.728 | H29: =C29+E29+F29+G29 -> 83.528
A30: =新增工艺设备!A29 -> 6 | B30: =新增工艺设备!B29 -> U肋反变形焊接系统 | C30: =SUM(C31:C32) -> 686.4 | D30: =SUM(D31:D32) -> 0 | E30: =SUM(E31:E32) -> 0 | F30: =SUM(F31:F32) -> 0 | G30: =SUM(G31:G32) -> 41.184 | H30: =SUM(H31:H32) -> 727.584 | I30: =SUM(I31:I32) -> 0 | J30: =SUM(J31:J32) -> 0 | K30: =SUM(K31:K32) -> 0
A31: =新增工艺设备!A30 -> 1 | B31: =新增工艺设备!B30 -> 可调式液压反变形胎架 | C31: =新增工艺设备!H30 -> 446.4 | D31: =新增工艺设备!I30 -> 0 | G31: =C31*6% -> 26.784 | H31: =C31+E31+F31+G31 -> 473.184
A32: =新增工艺设备!A31 -> 2 | B32: =新增工艺设备!B31 -> CO2气体保护焊机 | C32: =新增工艺设备!H31 -> 240 | D32: =新增工艺设备!I31 -> 0 | G32: =C32*6% -> 14.4 | H32: =C32+E32+F32+G32 -> 254.4
A33: =新增工艺设备!A32 -> （五） | B33: =新增工艺设备!B32 -> 板肋板单元生产线 | C33: =新增工艺设备!H32 -> 0 | D33: =新增工艺设备!I32 -> 0 | H33: =C33+E33+F33+G33 -> 0
A34: =新增工艺设备!A33 -> 1 | B34: =新增工艺设备!B33 -> 钢板对齐装配胎架 | C34: =新增工艺设备!H33 -> 40.4 | D34: =新增工艺设备!I33 -> 0 | G34: =C34*6% -> 2.424 | H34: =C34+E34+F34+G34 -> 42.824
A35: =新增工艺设备!A34 -> 2 | B35: =新增工艺设备!B34 -> 板肋定位装置 | C35: =新增工艺设备!H34 -> 24.2 | D35: =新增工艺设备!I34 -> 0 | G35: =C35*6% -> 1.452 | H35: =C35+E35+F35+G35 -> 25.652
A36: =新增工艺设备!A35 -> 3 | B36: =新增工艺设备!B35 -> 移动式板肋装配机 | C36: =新增工艺设备!H35 -> 289.9 | D36: =新增工艺设备!I35 -> 0 | G36: =C36*6% -> 17.394 | H36: =C36+E36+F36+G36 -> 307.294
A37: =新增工艺设备!A36 -> 4 | B37: =新增工艺设备!B36 -> 板肋板单元对齐压紧焊接胎架 | C37: =新增工艺设备!H36 -> 80.8 | D37: =新增工艺设备!I36 -> 0 | G37: =C37*6% -> 4.848 | H37: =C37+E37+F37+G37 -> 85.648
A38: =新增工艺设备!A37 -> 5 | B38: =新增工艺设备!B37 -> 十头双丝双边板肋龙门焊接机 | C38: =新增工艺设备!H37 -> 485.3 | D38: =新增工艺设备!I37 -> 0 | G38: =C38*6% -> 29.118 | H38: =C38+E38+F38+G38 -> 514.418 | K38: =C38*3% -> 14.559
A39: =新增工艺设备!A38 -> 6 | B39: =新增工艺设备!B38 -> 板肋板单元机械滚压矫正机 | C39: =新增工艺设备!H38 -> 445.1 | D39: =新增工艺设备!I38 -> 0 | G39: =C39*6% -> 26.706 | H39: =C39+E39+F39+G39 -> 471.806 | K39: =C39*3% -> 13.353
A40: =新增工艺设备!A39 -> （六） | B40: =新增工艺设备!B39 -> 横隔板单元件生产线 | C40: =新增工艺设备!H39 -> 0 | D40: =新增工艺设备!I39 -> 0 | H40: =C40+E40+F40+G40 -> 0
A41: =新增工艺设备!A40 -> 1 | B41: =新增工艺设备!B40 -> 钢板对齐装配胎架 | C41: =新增工艺设备!H40 -> 56.7 | D41: =新增工艺设备!I40 -> 0 | G41: =C41*6% -> 3.402 | H41: =C41+E41+F41+G41 -> 60.102
...

Sheet 公用设备表
A1: 附表1-4
A2: 公 用 设 备 表
G3: 单位：万元
A4: 序号 | B4: 名称 | C4: 规格型号 | D4: 单位 | E4: 数量 | F4: 单价 | G4: 合价 | H4: 备注
A5: 一 | B5: 电气工程
B6: 强电工程
A7: 1 | B7: 变压器 | C7: SCB11-630/10/0.4KV | D7: 台 | E7: 2 | F7: 18 | G7: =F7*E7 -> 36
A8: 2 | B8: 高压开关柜 | C8: HXGN15-12 | D8: 台 | E8: 4 | F8: 10 | G8: =F8*E8 -> 40
A9: 3 | B9: 抽屉式低压配电柜 | C9: GCS-12 | D9: 台 | E9: 9 | F9: 4 | G9: =F9*E9 -> 36
B10: 弱电工程
A11: 1 | B11: 综合布线系统 | C11: 209点 | D11: 套 | E11: 1 | F11: =209*3000/10000 -> 62.7 | G11: =F11*E11 -> 62.7
A12: 2 | B12: 火灾自动报警系统 | C12: 326点 | D12: 套 | E12: 1 | F12: =326*2000/10000 -> 65.2 | G12: =F12*E12 -> 65.2
B13: 小计 | G13: =SUM(G7:G12) -> 239.9
A15: 二 | B15: 暖通、空调工程
A16: 1 | B16: 离心风机箱 | C16: 型号：HYPA15-15A-II 风量：7700m3/h；全压：320Pa 功率：1.5KW 噪声：60dB(A ) | D16: 台 | E16: 1 | F16: 0.8 | G16: =F16*E16 -> 0.8
A17: 2 | B17: 斜流风机 | C17: 型号：GXF-7-A 风量：13952m3/h 风压：457Pa 功率：3kW | D17: 台 | E17: 2 | F17: 1 | G17: =F17*E17 -> 2
A18: 3 | B18: 混流风机 | C18: 型号：HL3-2A-2.5A 风量：1341m3/h；转速：1450r/min 全压：79Pa 功率：0.55KW | D18: 台 | E18: 1 | F18: 0.15 | G18: =F18*E18 -> 0.15
A19: 4 | B19: 混流风机 | C19: 型号：PYHL3-2AI-3.5A 风量：3680m3/h；转速：1450r/min 全压：154Pa 功率：0.55KW | D19: 台 | E19: 1 | F19: 0.3 | G19: =F19*E19 -> 0.3
A20: 5 | B20: 混流风机 | C20: 型号：HL3-2AI-3A 风量：1411m3/h；转速：960r/min 全压：56Pa 功率：0.75KW | D20: 台 | E20: 1 | F20: 0.15 | G20: =F20*E20 -> 0.15
A21: 6 | B21: 斜流风机 | C21: 型号：GXF-4-A 风量：4014m3/h；转速：1450r/min 全压：218Pa 功率：0.37KW | D21: 台 | E21: 2 | F21: 0.5 | G21: =F21*E21 -> 1
A22: 7 | B22: 风机盘管 | C22: 型号:FP-34;中档风量:270m3/h ; 中档冷量：1700W;中档热量：2720W 电量：41W 噪声：39dB(A) | D22: 台 | E22: 30 | F22: 0.12 | G22: =F22*E22 -> 3.6
A23: 8 | B23: 风机盘管 | C23: 型号:FP-51;中档风量:400m3/h 中档冷量：2295W;中档热量：3570W 电量：51W 噪声：41dB(A) | D23: 台 | E23: 29 | F23: 0.15 | G23: =F23*E23 -> 4.35
A24: 9 | B24: 风机盘管 | C24: 型号:FP-68;中档风量:540m3/h;中档冷量：3096W;中档热量：4644W 电量：71W 噪声：43dB(A) | D24: 台 | E24: 171 | F24: 0.16 | G24: =F24*E24 -> 27.36
A25: 10 | B25: 风机盘管 | C25: 型号:FP-85 ;中档风量:680m3/h ; 中档冷量：3870W;中档热量：5848W 电量：87W 噪声：45dB(A) | D25: 台 | E25: 8 | F25: 0.17 | G25: =F25*E25 -> 1.36
A26: 11 | B26: 风机盘管 | C26: 型号:FP-102 ;中档风量:810m3/h; 中档冷量：4816W;中档热量：7052W 电量：101W 噪声：46dB(A) | D26: 台 | E26: 12 | F26: 0.18 | G26: =F26*E26 -> 2.16
A27: 12 | B27: 风机盘管 | C27: 型号:FP-136 ;中档风量:1080m3/h; 中档冷量：6192W;中档热量：9288W 电量：138W 噪声：47dB(A) | D27: 台 | E27: 41 | F27: 0.2 | G27: =F27*E27 -> 8.2
A28: 13 | B28: 分体空调 | C28: 制热量：3.0Kw 制冷量：2.5Kw;功率：2.0Kw(220V/50Hz) | D28: 台 | E28: 3 | F28: 0.5 | G28: =F28*E28 -> 1.5
A29: 14 | B29: 恒温恒湿空调 | C29: 型号：HF12N;制冷量：12.6Kw 风量：3000m\/h ；功率：5.4Kw；空调室外机（室内外机高差35.80m） | D29: 台 | E29: 1 | F29: 2.5 | G29: =F29*E29 -> 2.5 | J29: =12.6/2.4*0.4 -> 2.1
A30: 15 | B30: 热泵机组 | C30: 型号：LSRF280 ；制冷量：279kW 制热量：297kW ；夏季供回水温度：7/12℃ ；冬季供回水温度：45/40℃ | D30: 台 | E30: 4 | F30: 35 | G30: =F30*E30 -> 140
A31: 16 | B31: 循环水泵 | C31: 型号：CDL110-20 ；流量：110m3/h；扬程：28m 电量：15Kw | D31: 台 | E31: 3 | F31: 1.5 | G31: =F31*E31 -> 4.5
A32: 17 | B32: 补水泵 | C32: 型号：CDL2-14 流量：2m3/h ；扬程：55m 电量：2.0Kw | D32: 台 | E32: 2 | F32: 0.6 | G32: =F32*E32 -> 1.2
A33: 18 | B33: 软化水处理器 | C33: 型号：TRB-250 处理量：1-2m3/h | D33: 台 | E33: 1 | F33: 1.5 | G33: =F33*E33 -> 1.5
A34: 19 | B34: 软化水箱 | C34: 外形尺寸：1400X1400X1200 | D34: 台 | E34: 1 | F34: 1 | G34: =F34*E34 -> 1
A35: 20 | B35: 定压罐 | C35: 型号：SN800-1.0；调节容积：0.26m3 总容积：0.86m3 | D35: 台 | E35: 1 | F35: 1 | G35: =F35*E35 -> 1
A36: 21 | B36: 新风机组 | C36: 型号：QGK-D-10-H ；送风风量：1000m3/h 6排表冷器冷量：9.6Kw ；水量：1.66m\/h 送风功率：0.2Kw | D36: 台 | E36: 1 | F36: 0.6 | G36: =F36*E36 -> 0.6
A37: 22 | B37: 新风机组 | C37: 型号：QGK-D-20-H；送风风量：2000m3/h 6排表冷器冷量：19.3Kw ；水量：3.31m\/h 送风功率：0.7Kw | D37: 台 | E37: 1 | F37: 0.8 | G37: =F37*E37 -> 0.8
A38: 23 | B38: 全热交换器新风机组 | C38: 型号：QGK-D-25-H;送风风量：2500m3/h 回风风量：2000m\/h ;水量：3.31m3/h 送风功率：0.7Kw | D38: 台 | E38: 1 | F38: 1 | G38: =F38*E38 -> 1
A39: 24 | B39: 全热交换器新风机组 | C39: 型号：QGK-D-30-H;送风风量：3000m3/h 回风风量：2400m3/h ；6排表冷器冷量：30.7Kw 水量：5.29m3/h ;送风功率：2.2Kw 排风功率：0.5Kw | D39: 台 | E39: 8 | F39: 1.2 | G39: =F39*E39 -> 9.6
A40: 25 | B40: 全热交换器新风机组 | C40: 型号：QGK-D-35-H;送风风量：3500m3/h 回风风量：2800m\/h ;6排表冷器冷量：34.6Kw 水量：5.94m\/h | D40: 台 | E40: 2 | F40: 1.5 | G40: =F40*E40 -> 3
A41: 26 | B41: 壁式轴流风机 | C41: 型号：SPF2.5-Z 风量：1000m3/h ;全压：52Pa 功率：0.06KW 噪声：60dB(A) | D41: 台 | E41: 1 | F41: 0.2 | G41: =F41*E41 -> 0.2
...

Sheet 新增工艺设备
A1: 附表2
A2: 新 增 工 艺 设 备 表
A3: ='[20]估算表1－1'!A3 -> 项目名称：武船重型工程股份有限公司双柳桥区办公楼及珠港澳大桥生产设备建设项目 | G3: 单位：万元、万美元
A4: 序号 | B4: 设 备 名 称 | C4: 规格型号或参考型号 及其主要技术（性能）指标 | D4: 国别 | E4: 单位 | F4: 数量 | G4: 设 备 价 格 | J4: 招标情况 | K4: 备注
G5: 单价 | H5: 合计 | I5: 其中外汇
A6: 一 | B6: 板单元生产线
A7: （一） | B7: 钢材预处理生产线
A8: 1.1 | B8: 钢板矫平机 | C8: 加工板厚10-40mm 最大板宽4500mm，数控七辊 | D8: 国产 | E8: 台 | F8: 1 | G8: 993.6 | H8: =G8*F8 -> 993.6 | J8: 不招标 | K8: 非标集成
A9: （二） | B9: 下料切割生产线
A10: 1 | B10: 数控等离子切割机 | C10: 30x6000x40000,自动编程、自动划线、坡口开制、喷码打标 | D10: 国产 | E10: 台 | F10: 1 | G10: 92.2 | H10: =G10*F10 -> 92.2
A11: 2 | B11: 数控火焰切割机 | C11: 100x6000x40000,自动编程、自动划线、坡口开制、喷码打标 | D11: 国产 | E11: 台 | F11: 2 | G11: 47.8 | H11: =G11*F11 -> 95.6
A12: 3 | B12: 门式多头火焰切割机 | C12: 100x6000x40000,横向割炬2付、纵向割炬15付 | D12: 国产 | E12: 台 | F12: 3 | G12: 34.5 | H12: =G12*F12 -> 103.5 | J12: 不招标 | K12: 非标集成
A13: 4 | B13: 数控划线号料机 | C13: 6000x40000,自动编程、自动划线、喷码打标 | D13: 国产 | E13: 台 | F13: 2 | G13: 49.3 | H13: =G13*F13 -> 98.6
A14: （三） | B14: U肋生产线
A15: 1 | B15: 坡口铣边机 | C15: 双45°坡口 宽度100-500mm | D15: 国产 | E15: 台 | F15: 1 | G15: 240 | H15: =G15*F15 -> 240 | J15: 不招标 | K15: 非标集成
A16: 2 | B16: 双头坡口铣边机 | C16: 最大长度15m 最大宽度5000m | D16: 国产 | E16: 台 | F16: 1 | G16: 70 | H16: =G16*F16 -> 70 | J16: 不招标 | K16: 非标集成
A17: 3 | B17: R2倒角机 | C17: 宽度100-500mm 速度10m/min | D17: 国产 | E17: 台 | F17: 1 | G17: 40 | H17: =G17*F17 -> 40 | J17: 不招标 | K17: 非标集成
A18: 4 | B18: U肋板矫平机 | C18: 矫平厚度4-16mm 最大宽度1100mm | D18: 国产 | E18: 台 | F18: 1 | G18: 90 | H18: =G18*F18 -> 90 | J18: 不招标 | K18: 非标集成
A19: 5 | B19: 数控多边坡口成型机 | C19: 最大加工长度：17000mm，最大加工板料宽度： 1100mm，最大加工板料厚度：10mm | D19: 国产 | E19: 台 | F19: 1 | G19: 372 | H19: =G19*F19 -> 372 | J19: 不招标 | K19: 非标集成
A20: 6 | B20: 双台联动电液伺服数控折弯机 | C20: 最大加工长度：18000m，最大加工板料厚度：12mm | D20: 国产 | E20: 台 | F20: 1 | G20: 404.5 | H20: =G20*F20 -> 404.5 | J20: 不招标 | K20: 非标集成
A21: （四） | B21: U肋板单元生产线
A22: 1 | B22: U肋端口栓孔定位装置 | C22: 轨距4500×2000，前后移动范围500 | D22: 国产 | E22: 套 | F22: 2 | G22: =6.9/2+24.5 -> 27.95 | H22: =G22*F22 -> 55.9
A23: 2 | B23: 移动式U肋装配机 | C23: 轨距6000×40000,总压力15t,行走速度10m/min | D23: 国产 | E23: 台 | F23: 2 | G23: =7.7+103.5 -> 111.2 | H23: =G23*F23 -> 222.4 | J23: 不招标 | K23: 非标集成
A24: 3 | B24: U肋龙门焊接系统 | E24: 套 | F24: 1 | H24: =SUM(H25:H26) -> 838.7 | J24: 不招标 | K24: 非标集成
A25: 1 | B25: U肋龙门焊接机 | C25: 轨距6000×40000,行走速度V=10m/min 焊接速度V=250-1000mm/min | D25: 国产 | E25: （台） | F25: 4 | G25: =35.5/4+170.8 -> 179.675 | H25: =G25*F25 -> 718.7
A26: 2 | B26: 逆变埋弧自动焊机 | C26: 1250A | D26: 国产 | E26: （台） | F26: 30 | G26: 4 | H26: =G26*F26 -> 120 | J26: 不招标 | K26: 非标集成
A27: 4 | B27: U肋板单元机械滚压矫正机 | C27: 工作速度6m/min,上辊矫正力100吨/个，前后各15米输送辊道 | D27: 国产 | E27: 台 | F27: 1 | G27: =60.1+357.8 -> 417.9 | H27: =G27*F27 -> 417.9 | J27: 不招标 | K27: 非标集成
A28: 5 | B28: 底板对齐装配胎架 | C28: 轨距5000×40000,每隔4米放置一个侧边对齐装置 | D28: 国产 | E28: 套 | F28: 2 | G28: 39.4 | H28: =G28*F28 -> 78.8
A29: 6 | B29: U肋反变形焊接系统 | F29: 1 | H29: =SUM(H30:H31) -> 686.4
A30: 1 | B30: 可调式液压反变形胎架 | C30: 正后方向倾斜0～±30° | D30: 国产 | E30: （套） | F30: 8 | G30: 55.8 | H30: =G30*F30 -> 446.4 | J30: 不招标 | K30: 非标集成
A31: 2 | B31: CO2气体保护焊机 | C31: 500A | D31: 国产 | E31: （台） | F31: 200 | G31: 1.2 | H31: =G31*F31 -> 240 | J31: 不招标 | K31: 非标集成
A32: （五） | B32: 板肋板单元生产线
A33: 1 | B33: 钢板对齐装配胎架 | C33: 轨距5000×40000，每隔4m放置一个侧边对齐压紧装置 | D33: 国产 | E33: 套 | F33: 1 | G33: 40.4 | H33: =G33*F33 -> 40.4
A34: 2 | B34: 板肋定位装置 | C34: 轨距4500，前后行程500mm | D34: 国产 | E34: 套 | F34: 2 | G34: =0.5+11.6 -> 12.1 | H34: =G34*F34 -> 24.2
A35: 3 | B35: 移动式板肋装配机 | C35: 轨距6000×20000，行走速度V=2-10m/min，多根板肋双面自动点焊 | D35: 国产 | E35: 台 | F35: 2 | G35: =36.5/2+126.7 -> 144.95 | H35: =G35*F35 -> 289.9 | J35: 不招标 | K35: 非标集成
A36: 4 | B36: 板肋板单元对齐压紧焊接胎架 | C36: 每隔3m放置一个侧边对齐压紧装置，行程2000mm | D36: 国产 | E36: 套 | F36: 1 | G36: 80.8 | H36: =G36*F36 -> 80.8
A37: 5 | B37: 十头双丝双边板肋龙门焊接机 | C37: 行走速度V=10m/min，双丝焊，焊接速度V=250-1000mm/min | D37: 国产 | E37: 台 | F37: 2 | G37: =50.5/2+217.4 -> 242.65 | H37: =G37*F37 -> 485.3 | J37: 不招标 | K37: 非标集成
A38: 6 | B38: 板肋板单元机械滚压矫正机 | C38: V=6m/min,矫正力100吨/个，前后辊道各15米 | D38: 国产 | E38: 台 | F38: 1 | G38: =60.1+385 -> 445.1 | H38: =G38*F38 -> 445.1 | J38: 不招标 | K38: 非标集成
A39: （六） | B39: 横隔板单元件生产线
A40: 1 | B40: 钢板对齐装配胎架 | C40: 主要由450×450梅花排放的活动套管组成，一侧面设有板边定位死挡和钢板压紧装置 | D40: 国产 | E40: 套 | F40: 1 | G40: 56.7 | H40: =G40*F40 -> 56.7
...

Sheet 汇总表
B2: 单项工程投资构成表 | M2: 地上 | N2: 地下
B3: 序号 | C3: 工程费用名称 | D3: 估算价值（万元） | H3: 技术经济指标 | K3: 现 | L3: 31579.6 | M3: 23152.8 | N3: 8873
D4: 建筑工程 | E4: 安装工程 | F4: 公用设备 | G4: 合计 | H4: 数量 M2 | I4: 单位价值 元/M2
B5: 一 | C5: 工程费用
B6: 1 | C6: 建筑装饰工程
B7: 1.1 | C7: 建筑工程 | D7: =土费!G28/10000 -> 2114.5793 | G7: =SUM(D7:F7) -> 2114.5793 | H7: =总概!D8 -> 12222.11 | I7: =D7/H7*10000 -> 1730.1263
B8: 1.2 | C8: 装饰工程 | D8: =土费!G58/10000 -> 1295.4604 | G8: =SUM(D8:F8) -> 1295.4604 | H8: =H7 -> 12222.11 | I8: =D8/H8*10000 -> 1059.9319
B9: 1.3 | C9: 精装工程 | D9: =H9*I9/10000 -> 855.5477 | G9: =SUM(D9:F9) -> 855.5477 | H9: =H8*0.35 -> 4277.7385 | I9: 2000
C11: 小计 | D11: =SUM(D7:D10) -> 4265.5875 | E11: =SUM(E7:E10) -> 0 | F11: =SUM(F7:F10) -> 0 | G11: =SUM(G7:G10) -> 4265.5875 | I11: =G11/H7*10000 -> 3490.0582
B13: 2 | C13: 安装工程
B14: 2.1 | C14: 给排水及消防工程 | E14: =水费!G31/10000 -> 137.63698 | F14: =公用设备表!G52 -> 3 | G14: =SUM(D14:F14) -> 140.63698 | H14: =H8 -> 12222.11 | I14: =G14/H14*10000 -> 115.06768 | J14: =[18]公用设备材料表!H22 -> 398.965 | K14: =J14/H14*10000 -> 326.42891 | N14: 530
B15: 2.2 | C15: 暖通动力工程 | E15: =暖费!G31/10000 -> 269.69616 | F15: =公用设备表!G47 -> 227.33 | G15: =SUM(D15:F15) -> 497.02616 | H15: =H14 -> 12222.11 | I15: =G15/H15*10000 -> 406.6615 | J15: =[18]公用设备材料表!H68 -> 842.67 | K15: =J15/H15*10000 -> 689.4636 | L15: 750 | M15: =L15-K15 -> 60.536397 | N15: 750
B16: 2.3 | C16: 电气工程 | E16: =电费!G31/10000 -> 274.95907 | F16: =公用设备表!G13 -> 239.9 | G16: =SUM(D16:F16) -> 514.85907 | H16: =H15 -> 12222.11 | I16: =G16/H16*10000 -> 421.2522 | J16: =[18]公用设备材料表!H86 -> 862 | K16: =J16/H16*10000 -> 705.2792 | L16: 700 | M16: =L16-K16 -> -5.279203 | N16: 990
B17: 2.4 | C17: 电梯工程 | F17: =公用设备表!G54 -> 180 | G17: =SUM(D17:F17) -> 180
C19: 小计 | D19: =SUM(D14:D16) -> 0 | E19: =SUM(E14:E17) -> 682.29221 | F19: =SUM(F14:F17) -> 650.23 | G19: =SUM(G14:G17) -> 1332.5222 | H19: =SUM(H14:H17) -> 36666.33 | I19: =G19/H14*10000 -> 1090.2555
C21: 合计 | D21: =D19+D11 -> 4265.5875 | E21: =E19+E11 -> 682.29221 | F21: =F19+F11 -> 650.23 | G21: =G19+G11 -> 5598.1097 | I21: =I19+I11 -> 4580.3136 | K21: =G21/H7*10000 -> 4580.3136
C24: 建设期利息 | D24: 1 | E24: 2 | F24: 3
C25: 0.0655 | D25: 0.2 | E25: 0.4 | F25: 0.4
C26: =C27*C28 -> 18740 | D26: =D25*$C$26 -> 3748 | E26: =E25*$C$26 -> 7496 | F26: =F25*$C$26 -> 7496 | H26: =C26*2 -> 37480
B27: =D27+E27+F27 -> 1595.711 | C27: 0.5 | D27: =D26*C25/2 -> 122.747 | E27: =(D26+E26/2)*C25 -> 490.988 | F27: =(D26+E26+F26/2)*C25 -> 981.976
B28: =C26+C32 -> 37480 | C28: =[18]估算表!K63 -> 37480 | D28: =D26 -> 3748 | E28: =D26+E26 -> 11244 | F28: =D26+E26+F26 -> 18740
C30: 自筹
C31: =1-C27 -> 0.5 | D31: =D25*$C$28*$C$31 -> 3748 | E31: =E25*$C$28*$C$31 -> 7496 | F31: =F25*$C$28*$C$31 -> 7496
C32: =SUM(D31:F31) -> 18740
C34: 建设期利息 | D34: 1 | E34: 2 | F34: 3
C35: 0.0655 | D35: 0.2 | E35: 0.4 | F35: 0.4
C36: =C37*C38 -> 26236 | D36: =D35*$C$36 -> 5247.2 | E36: =E35*$C$36 -> 10494.4 | F36: =F35*$C$36 -> 10494.4
B37: =D37+E37+F37 -> 2233.9954 | C37: 0.7 | D37: =D36*C35/2 -> 171.8458 | E37: =(D36+E36/2)*C35 -> 687.3832 | F37: =(D36+E36+F36/2)*C35 -> 1374.7664
B38: =C36+C42 -> 37480 | C38: =C28 -> 37480 | D38: =D36 -> 5247.2 | E38: =D36+E36 -> 15741.6 | F38: =D36+E36+F36 -> 26236
C40: 自筹
C41: =1-C37 -> 0.3 | D41: =D35*$C$28*$C$41 -> 2248.8 | E41: =E35*$C$28*$C$41 -> 4497.6 | F41: =F35*$C$28*$C$41 -> 4497.6
C42: =SUM(D41:F41) -> 11244
C44: 建设期利息 | D44: 1 | E44: 2 | F44: 3
C45: 0.0655 | D45: 0.2 | E45: 0.4 | F45: 0.4
C46: =C47*C48 -> 37480 | D46: =D45*$C$46 -> 7496 | E46: =E45*$C$46 -> 14992 | F46: =F45*$C$46 -> 14992
B47: =D47+E47+F47 -> 3191.422 | C47: 1 | D47: =D46*C45/2 -> 245.494 | E47: =(D46+E46/2)*C45 -> 981.976 | F47: =(D46+E46+F46/2)*C45 -> 1963.952
B48: =C46+C52 -> 37480 | C48: =C38 -> 37480 | D48: =D46 -> 7496 | E48: =D46+E46 -> 22488 | F48: =D46+E46+F46 -> 37480
C50: 自筹
C51: =1-C47 -> 0 | D51: =D45*$C$28*$C$51 -> 0 | E51: =E45*$C$28*$C$51 -> 0 | F51: =F45*$C$28*$C$51 -> 0
C52: =SUM(D51:F51) -> 0

Sheet 土费
A2: 单位工程费用汇总表
A3: 工程名称：2601#土建工程 | E3: 第 1 页 共 2 页
A4: 序号 | B4: 费用名称 | D4: 取费基数 | F4: 费率 | G4: 费用金额
A5: 1 | B5: 建筑工程12层以上 | D5: 建筑工程12层以上 | G5: 21145793
A6: 一 | B6: 分部分项工程费（含5%零星工程） | D6: (人工费+材料费+未计价材料费+施工机具使用费)*1.05 | G6: 13393177
A7: 1 | B7: 人工费 | D7: 人工费 | G7: 2087434
A8: 2 | B8: 材料费 | D8: 材料费 | G8: 9617986.6
A9: 3 | B9: 未计价材料费 | D9: 主材费
A10: 4 | B10: 施工机具使用费 | D10: 机械费 | G10: 1049986.2
A11: 二 | B11: 措施项目费 | D11: 单价措施项目费+总价措施项目费 | G11: 3570092.9
A12: 2.1 | B12: 单价措施项目费 | D12: 人工费+材料费+施工机具使用费 | G12: 2887867.6
A13: 2.1.1 | B13: 人工费 | D13: 技术措施项目人工费 | G13: 1901708.8
A14: 2.1.2 | B14: 材料费 | D14: 技术措施项目材料费 | G14: 841205.19
A15: 2.1.3 | B15: 施工机具使用费 | D15: 技术措施项目机械费 | G15: 144953.65
A16: 2.2 | B16: 总价措施项目费 | D16: 安全文明施工费+其它总价措施项目费 | G16: 682225.29
A17: 2.2.1 | B17: 安全文明施工费 | D17: 人工费+施工机具使用费+人工费+施工机具使用费 | F17: 12.51 | G17: 648528.75
A18: 2.2.2 | B18: 其它总价措施项目费 | D18: 人工费+施工机具使用费+人工费+施工机具使用费 | F18: 0.65 | G18: 33696.54
A19: 三 | B19: 总包服务费
A20: 四 | B20: 企业管理费 | D20: 人工费+施工机具使用费+人工费+施工机具使用费 | F20: 23.84 | G20: 1235885.3
A21: 五 | B21: 利润 | D21: 人工费+施工机具使用费+人工费+施工机具使用费 | F21: 18.17 | G21: 941947.83
A22: 六 | B22: 规费 | D22: 人工费+施工机具使用费+人工费+施工机具使用费 | F22: 24.72 | G22: 1281505.2
A23: 七 | B23: 索赔与现场签证
A24: 八 | B24: 不含税工程造价 | D24: 分部分项工程费（含5%零星工程）+措施项目费+总包服务费+企业管理费+利润+规费+索赔与现场签证 | G24: 20422608
A25: 九 | B25: 税前包干项目 | D25: 税前包干价
A26: 十 | B26: 税金 | D26: 不含税工程造价+税前包干价 | F26: 3.5411 | G26: 723184.99
A27: 十一 | B27: 税后包干项目 | D27: 税后包干价
A28: 十二 | B28: 含税工程造价 | D28: 不含税工程造价+税金+税前包干项目+税后包干项目 | G28: 21145793
A30: 2 | B30: 装饰工程 | D30: 装饰工程 | G30: 12954604
A31: 一 | B31: 分部分项工程费（含5%零星工程） | D31: (人工费+材料费+未计价材料费+施工机具使用费)*1.05 | G31: 11125023
A32: 1 | B32: 人工费 | D32: 人工费 | G32: 1500489.7
A33: 2 | B33: 材料费 | D33: 材料费 | G33: 9060053.2
A34: 3 | B34: 未计价材料费 | D34: 主材费
A35: 4 | B35: 施工机具使用费 | D35: 机械费 | G35: 34717.17
A36: 编制人: | C36: 审核人: | E36: 编制日期:
A38: 单位工程费用汇总表
A39: 工程名称：2601#土建工程 | E39: 第 2 页 共 2 页
A40: 序号 | B40: 费用名称 | D40: 取费基数 | F40: 费率 | G40: 费用金额
A41: 二 | B41: 措施项目费 | D41: 单价措施项目费+总价措施项目费 | G41: 605804.19
A42: 2.1 | B42: 单价措施项目费 | D42: 人工费+材料费+施工机具使用费 | G42: 480405.93
A43: 2.1.1 | B43: 人工费 | D43: 技术措施项目人工费 | G43: 305102.98
...

Sheet 土
A2: 单位工程预结算书
A3: 工程名称：2601#土建工程 | L3: 第 1 页 共 7 页
A4: 序号 | B4: 编号 | C4: 定额名称 | D4: 单位 | E4: 工程量 | G4: 单价（元） | H4: 其中（元） | K4: 合价 | M4: 其中（元）
H5: 人工费单价 | I5: 材料费单价 | J5: 机械费单价 | M5: 人工费合价 | N5: 材料费合价 | O5: 机械费合价
C6: 010105、砌块砌体 | K6: 936010.45 | M6: 254593.39 | N6: 677347.4 | O6: 4069.67
A7: 1 | B7: A1-46 | C7: 加气混凝土砌块墙 600*300*(125、200、250) 混合砂浆M5 外墙 | D7: 10m3 | E7: 121.9 | G7: 3300.46 | H7: 897.72 | I7: 2388.39 | J7: 14.35 | K7: 402326.07 | M7: 109432.07 | N7: 291144.74 | O7: 1749.27
A8: 2 | B8: A1-46 | C8: 加气混凝土砌块墙 600*300*(125、200、250) 混合砂浆M5 内墙 | D8: 10m3 | E8: 161.7 | G8: 3300.46 | H8: 897.72 | I8: 2388.39 | J8: 14.35 | K8: 533684.38 | M8: 145161.32 | N8: 386202.66 | O8: 2320.4
C9: 010201、现场搅拌混凝土 | K9: 2807838.3 | M9: 697889.45 | N9: 2048585.3 | O9: 61363.59
A10: 3 | B10: A2-17换 | C10: 矩形柱 C20现浇混凝土换为【C40碎石混凝土】 | D10: 10m3 | E10: 53.7 | G10: 4938.77 | H10: 1263.88 | I10: 3572.11 | J10: 102.78 | K10: 265211.95 | M10: 67870.36 | N10: 191822.31 | O10: 5519.29
A11: 4 | B11: A2-17 H1-55 1-79 | C11: 矩形柱 C20现浇混凝土换为【C30碎石混凝土】换为【C35碎石混凝土】 | D11: 10m3 | E11: 12.7 | G11: 4608.79 | H11: 1263.88 | I11: 3242.13 | J11: 102.78 | K11: 58531.63 | M11: 16051.28 | N11: 41175.05 | O11: 1305.31
A12: 5 | B12: A2-23换 | C12: 单梁、连续梁、悬臂梁 C20现浇混凝土换为【C35碎石混凝土】 | D12: 10m3 | E12: 82.8 | G12: 4636.22 | H12: 1043.72 | I12: 3489.72 | J12: 102.78 | K12: 383879.02 | M12: 86420.02 | N12: 288948.82 | O12: 8510.18
A13: 6 | B13: A2-23换 | C13: 单梁、连续梁、悬臂梁 C20现浇混凝土换为【C30碎石混凝土】 | D13: 10m3 | E13: 56.5 | G13: 4720.26 | H13: 1043.72 | I13: 3573.76 | J13: 102.78 | K13: 266694.69 | M13: 58970.18 | N13: 201917.44 | O13: 5807.07
A14: 7 | B14: A2-29换 | C14: 直形混凝土墙 C20现浇混凝土换为【C40 | D14: 10m3 | E14: 79.9 | G14: 4978.13 | H14: 1191.92 | I14: 3683.43 | J14: 102.78 | K14: 397752.59 | M14: 95234.41 | N14: 294306.06 | O14: 8212.12
A15: 编制人: | F15: 审核人: | L15: 编制日期:
A17: 单位工程预结算书
A18: 工程名称：2601#土建工程 | L18: 第 2 页 共 7 页
A19: 序号 | B19: 编号 | C19: 定额名称 | D19: 单位 | E19: 工程量 | G19: 单价（元） | H19: 其中（元） | K19: 合价 | M19: 其中（元）
H20: 人工费单价 | I20: 材料费单价 | J20: 机械费单价 | M20: 人工费合价 | N20: 材料费合价 | O20: 机械费合价
C21: 碎石混凝土】
A22: 8 | B22: A2-29换 | C22: 直形混凝土墙 C20现浇混凝土换为【C35碎石混凝土】 | D22: 10m3 | E22: 25 | G22: 4714.84 | H22: 1191.92 | I22: 3420.14 | J22: 102.78 | K22: 117871 | M22: 29798 | N22: 85503.5 | O22: 2569.5
A23: 9 | B23: A2-30 H1-55 1-80 | C23: 直形混凝土墙 C20现浇混凝土换为【C40碎石混凝土、抗渗】 | D23: 10m3 | E23: 37.3 | G23: 5239.93 | H23: 1703.6 | I23: 3433.55 | J23: 102.78 | K23: 195449.39 | M23: 63544.28 | N23: 128071.42 | O23: 3833.69
A24: 10 | B24: A2-38换 | C24: 有梁板 C20现浇混凝土换为【C30碎石混凝土】 | D24: 10m3 | E24: 22.4 | G24: 4504.86 | H24: 1130.28 | I24: 3271.8 | J24: 102.78 | K24: 100908.86 | M24: 25318.27 | N24: 73288.32 | O24: 2302.27
A25: 11 | B25: A2-38换 | C25: 有梁板 C20现浇混凝土换为【C35碎石混凝土】 | D25: 10m3 | E25: 182.9 | G25: 4786.82 | H25: 1130.28 | I25: 3553.76 | J25: 102.78 | K25: 875509.38 | M25: 206728.21 | N25: 649982.7 | O25: 18798.46
A26: 12 | B26: A2-50换 | C26: 整体楼梯 C20现浇混凝土换为【C30碎石混凝土】 | D26: 10m2 | E26: 65 | G26: 1341.45 | H26: 444.88 | I26: 857.42 | J26: 39.15 | K26: 87194.25 | M26: 28917.2 | N26: 55732.3 | O26: 2544.75
A27: 13 | B27: A2-55 | C27: 台阶 C20现浇混凝土 | D27: 10m2 | E27: 11 | G27: 645.46 | H27: 168.24 | I27: 449.49 | J27: 27.73 | K27: 7100.06 | M27: 1850.64 | N27: 4944.39 | O27: 305.03
A28: 14 | B28: A2-57 | C28: 雨棚 C20现浇混凝土 | D28: 10m3 | E28: 3.5 | G28: 4833.3 | H28: 1499.24 | I28: 3170.92 | J28: 163.14 | K28: 16916.55 | M28: 5247.34 | N28: 11098.22 | O28: 570.99
A29: 15 | B29: A2-57 | C29: 零星构件 C20现浇混凝土 | D29: 10m3 | E29: 3 | G29: 4833.3 | H29: 1499.24 | I29: 3170.92 | J29: 163.14 | K29: 14499.9 | M29: 4497.72 | N29: 9512.76 | O29: 489.42
A30: 16 | B30: A2-60 | C30: 砼散水面层一次抹光 C15现浇混凝土 | D30: 100m2 | E30: 1.64 | G30: 2969.05 | H30: 787.12 | I30: 2056.16 | J30: 125.77 | K30: 4869.24 | M30: 1290.88 | N30: 3372.1 | O30: 206.26
A31: 17 | B31: A2-61 | C31: 防滑坡道 1:2水泥砂浆 | D31: 100m2 | E31: 8.2 | G31: 1884.12 | H31: 750.08 | I31: 1086.57 | J31: 47.47 | K31: 15449.78 | M31: 6150.66 | N31: 8909.87 | O31: 389.25
C32: 010202、商品混凝土 | K32: 339739.29 | M32: 29914.97 | N32: 309824.32
A33: 编制人: | F33: 审核人: | L33: 编制日期:
A35: 单位工程预结算书
A36: 工程名称：2601#土建工程 | L36: 第 3 页 共 7 页
A37: 序号 | B37: 编号 | C37: 定额名称 | D37: 单位 | E37: 工程量 | G37: 单价（元） | H37: 其中（元） | K37: 合价 | M37: 其中（元）
H38: 人工费单价 | I38: 材料费单价 | J38: 机械费单价 | M38: 人工费合价 | N38: 材料费合价 | O38: 机械费合价
A39: 18 | B39: A2-74换 | C39: 独立式桩承台 C20商品混凝土换为【商品混凝土C30】 | D39: 10m3 | E39: 67.98 | G39: 4561.28 | H39: 404.8 | I39: 4156.48 | K39: 310075.81 | M39: 27518.3 | N39: 282557.51
A40: 19 | B40: A2-75换 | C40: 基础垫层 C10商品混凝土换为【商品混凝土C15 碎石20】 | D40: 10m3 | E40: 0.98 | G40: 3910.66 | H40: 428.48 | I40: 3482.18 | K40: 3832.45 | M40: 419.91 | N40: 3412.54
A41: 20 | B41: A2-85换 | C41: 基础梁 C20商品混凝土换为【商品混凝土C30 】 | D41: 10m3 | E41: 5.7 | G41: 4531.76 | H41: 346.8 | I41: 4184.96 | K41: 25831.03 | M41: 1976.76 | N41: 23854.27
C42: 010206、钢筋及铁件 | K42: 5917902 | M42: 804547.44 | N42: 4989209 | O42: 124145.56
A43: 21 | B43: A2-453 | C43: 现浇构件螺纹钢筋(mm以外) φ12 | D43: t | E43: 659 | G43: 5368.52 | H43: 756.92 | I43: 4548.64 | J43: 62.96 | K43: 3537854.7 | M43: 498810.28 | N43: 2997553.8 | O43: 41490.64
...

Sheet 土措
D2: 单价措施项目分项汇总表
A3: 工程名称：2601#土建工程 | J3: 第 1 页 共 2 页
A4: 序号 | B4: 定额编码 | C4: 子目名称 | E4: 工程量 | G4: 价值（元） | I4: 其中（元）
E5: 单位 | F5: 数量 | G5: 单价 | H5: 合价 | I5: 人工费合价 | K5: 材料费合价 | L5: 机械费合价
B6: 一 | C6: 排水降水
B7: 二 | C7: 混凝土、钢筋混凝土模板及支撑 | H7: 2887867.7 | I7: 1901708.8 | K7: 841205.19 | L7: 144953.65
A8: 1 | B8: A7-39 | C8: 矩形柱 组合钢模板 钢支撑 | E8: 100m2 | F8: 53.7 | G8: 5262.52 | H8: 282597.32 | I8: 184674.3 | K8: 86269.05 | L8: 11653.97
A9: 2 | B9: A7-39 | C9: 矩形柱 组合钢模板 钢支撑 | E9: 100m2 | F9: 12.7 | G9: 5262.52 | H9: 66834 | I9: 43675.3 | K9: 20402.55 | L9: 2756.15
A10: 3 | B10: A7-54 | C10: 单梁、连续梁 组合钢模板 钢支撑 | E10: 100m2 | F10: 73.6092 | G10: 5857.3 | H10: 431151.17 | I10: 306323.21 | K10: 98904.27 | L10: 25923.69
A11: 4 | B11: A7-54 | C11: 单梁、连续梁 组合钢模板 钢支撑 | E11: 100m2 | F11: 50.2285 | G11: 5857.3 | H11: 294203.39 | I11: 209024.9 | K11: 67489.02 | L11: 17689.47
A12: 5 | B12: A7-73 | C12: 直形墙 组合钢模板 钢支撑 | E12: 100m2 | F12: 115.056 | G12: 3399.15 | H12: 391092.6 | I12: 268706.38 | K12: 101356.28 | L12: 21029.94
A13: 6 | B13: A7-73 | C13: 直形墙 组合钢模板 钢支撑 | E13: 100m2 | F13: 36 | G13: 3399.15 | H13: 122369.4 | I13: 84075.84 | K13: 31713.48 | L13: 6580.08
A14: 7 | B14: A7-76 | C14: 电梯井壁 组合钢模板 钢支撑 | E14: 100m2 | F14: 42.8577 | G14: 4246.28 | H14: 181985.79 | I14: 128338.24 | K14: 46592.32 | L14: 7055.23
A15: 8 | B15: A7-86 | C15: 有梁板 组合钢模板 钢支撑 | E15: 100m2 | F15: 15.6352 | G15: 5491.71 | H15: 85863.98 | I15: 56209.79 | K15: 24808.68 | L15: 4845.5
A16: 9 | B16: A7-86 | C16: 有梁板 组合钢模板 钢支撑 | E16: 100m2 | F16: 127.6642 | G16: 5491.71 | H16: 701094.76 | I16: 458963.01 | K16: 202567.34 | L16: 39564.41
A17: 10 | B17: A7-109 | C17: 楼梯 直形 木模板木支撑 | E17: 10m2 | F17: 65 | G17: 1747.6 | H17: 113594 | I17: 57959.2 | K17: 53129.7 | L17: 2505.1
A18: 11 | B18: A7-113 | C18: 台阶 木模板木支撑 | E18: 10m2 | F18: 11 | G18: 398.21 | H18: 4380.31 | I18: 2380.84 | K18: 1941.83 | L18: 57.64
A19: 12 | B19: A7-118 | C19: 零星构件 木模板木支撑 | E19: 100m2 | F19: 7.6405 | G19: 9437.33 | H19: 72105.92 | I19: 29177.85 | K19: 41570.05 | L19: 1358.02
A20: 13 | B20: A7-118 | C20: 零星构件 木模板木支撑 | E20: 100m2 | F20: 6.549 | G20: 9437.33 | H20: 61805.07 | I20: 25009.58 | K20: 35631.47 | L20: 1164.02
A21: 14 | B21: A7-121 | C21: 混凝土散水 钢模板木支撑 | E21: 100m2 | G21: 193.68
A22: 15 | B22: A7-28 | C22: 独立式桩承台 组合钢模板 木支撑 | E22: 100m2 | F22: 12.50832 | G22: 4461.75 | H22: 55809 | I22: 33532.8 | K22: 20273.11 | L22: 2003.08
A23: 16 | B23: A7-30 | C23: 混凝土基础垫层 木模板 木支撑 | E23: 100m2 | F23: 0.13524 | G23: 4660.45 | H23: 630.28 | I23: 145.62 | K23: 477.67 | L23: 6.99
A24: 17 | B24: A7-50 | C24: 基础梁 组合钢模板 钢支撑 | E24: 100m2 | F24: 4.7481 | G24: 4707.29 | H24: 22350.68 | I24: 13511.95 | K24: 8078.37 | L24: 760.36
B25: 三 | C25: 脚手架 | H25: 173564.96 | I25: 86336.99 | K25: 74463.21 | L25: 12764.77
A26: 1 | B26: A21-8 | C26: 综合脚手架 | E26: 100m2 | F26: 122.2211 | G26: 1420.09 | H26: 173564.96 | I26: 86336.99 | K26: 74463.21 | L26: 12764.77
C28: 页合计 | H28: 3061432.6 | I28: 1988045.8 | K28: 915668.4 | L28: 157718.42
A29: 编制人: | D29: 审核人: | J29: 编制日期:
D31: 单价措施项目分项汇总表
A32: 工程名称：2601#土建工程 | J32: 第 2 页 共 2 页
A33: 序号 | B33: 定额编码 | C33: 子目名称 | E33: 工程量 | G33: 价值（元） | I33: 其中（元）
E34: 单位 | F34: 数量 | G34: 单价 | H34: 合价 | I34: 人工费合价 | K34: 材料费合价 | L34: 机械费合价
B35: 四 | C35: 垂直运输费 | H35: 306840.96 | I35: 218765.99 | L35: 88074.97
A36: 1 | B36: A22-4 | C36: 垂直运输工程 13~15层 檐高(m以内) 49.5 | E36: 100m2 | F36: 122.2211 | G36: 2510.54 | H36: 306840.96 | I36: 218765.99 | L36: 88074.97
B37: 五 | C37: 大型机械设备进出场及安拆费
B38: 六 | C38: 已完工程及设备保护费
B39: 七 | C39: 地上、地下设施、建筑物临时保护设施费
B40: 八 | C40: 其他
C54: 页合计 | H54: 306840.96 | I54: 218765.99 | L54: 88074.97
C55: 合计 | H55: 3368273.6 | I55: 2206811.8 | K55: 915668.4 | L55: 245793.39
A56: 编制人: | D56: 审核人: | J56: 编制日期:

Sheet 土差
A2: 单位工程人材机价差表
A3: 工程名称：2601#土建工程 | I3: 第 1 页 共 2 页
A4: 序号 | B4: 材料名称 | C4: 材料规格 | D4: 单位 | F4: 材料量 | G4: 预算价 | H4: 市场价 | J4: 价 差 | K4: 价差合计
A5: 1 | B5: 成品钢质防火门 | D5: m2 | F5: 315.2758 | G5: 590 | H5: 800 | J5: 210 | K5: 66207.92
A6: 2 | B6: 实木装饰门(成品) | D6: m2 | F6: 460.94 | G6: 550 | H6: 800 | J6: 250 | K6: 115235
A7: 3 | B7: 铝合金外门 | D7: m2 | F7: 10.4425 | G7: 350 | H7: 1500 | J7: 1150 | K7: 12008.88
A8: 4 | B8: 断桥铝合金窗 | D8: m2 | F8: 1446.4778 | G8: 253 | H8: 800 | J8: 547 | K8: 791223.36
A9: 5 | B9: 玻璃棉高级吸声板 | D9: m2 | F9: 244.65 | G9: 133 | H9: 160 | J9: 27 | K9: 6605.55
A10: 6 | B10: 花岗岩板 | D10: m2 | F10: 3621 | G10: 185 | H10: 800 | J10: 615 | K10: 2226915
A11: 7 | B11: 石膏板 | D11: m2 | F11: 9896.25 | G11: 9.2 | H11: 80 | J11: 70.8 | K11: 700654.5
A12: 8 | B12: 复合地板 | D12: m2 | F12: 244.65 | G12: 155 | H12: 180 | J12: 25 | K12: 6116.25
A13: 9 | B13: 陶瓷锦砖 | D13: m2 | F13: 8014.66 | G13: 11.35 | H13: 80 | J13: 68.65 | K13: 550206.41
A14: 10 | B14: 防滑地砖 | D14: m2 | F14: 407.04 | G14: 11.35 | H14: 120 | J14: 108.65 | K14: 44224.9
A15: 11 | B15: 玻化砖 | D15: m2 | F15: 1859.48 | G15: 11.35 | H15: 150 | J15: 138.65 | K15: 257816.9
A16: 12 | B16: 面砖防水 | D16: m2 | F16: 1515.395 | G16: 11.35 | H16: 120 | J16: 108.65 | K16: 164647.67
... A25: 21 | B25: 钢制复合防火卷帘门 | D25: m2 | F25: 210.3192 | G25: 280 | H25: 800 | J25: 520 | K25: 109365.98
A26: 22 | B26: 复合双面自粘橡胶沥青防水卷材 | C26: 3mm | D26: m2 | F26: 2647.5454 | G26: 40.2 | H26: 50 | J26: 9.8 | K26: 25945.94
A27: 编制人: | E27: 审核人: | I27: 编制日期:
A29: 单位工程人材机价差表
A30: 工程名称：2601#土建工程 | I30: 第 2 页 共 2 页
A31: 序号 | B31: 材料名称 | C31: 材料规格 | D31: 单位 | F31: 材料量 | G31: 预算价 | H31: 市场价 | J31: 价 差 | K31: 价差合计
A32: 23 | B32: SBS改性沥青防水卷材玻纤胎 | C32: 3mm | D32: m2 | F32: 1469.6616 | G32: 32 | H32: 45 | J32: 13 | K32: 19105.6
A33: 24 | B33: 聚苯乙烯泡沫塑料板 | C33: 3mm | D33: m2 | F33: 2647.5454 | G33: 32 | H33: 40 | J33: 8 | K33: 21180.36
A55: 合 计 | K55: 5667073.6
A56: 编制人: | E56: 审核人: | I56: 编制日期:

Sheet 水费
A2: 单位工程费用汇总表
A3: 工程名称：2601#给排水工程 | E3: 第 1 页 共 1 页
A4: 序号 | B4: 费用名称 | D4: 取费基数 | F4: 费率 | G4: 费用金额
A5: 1 | B5: 安装工程 | D5: 安装工程 | G5: 1376369.8
A6: 一 | B6: 分部分项工程费（含5%零星工程） | D6: (人工费+材料费+未计价材料费+施工机具使用费)*1.05 | G6: 1239179.8
A7: 1 | B7: 人工费 | D7: 人工费 | G7: 159933.29
A8: 2 | B8: 材料费 | D8: 材料费 | G8: 84606.05
A9: 3 | B9: 未计价材料费 | D9: 主材费 | G9: 927965.83
A10: 4 | B10: 施工机具使用费 | D10: 机械费 | G10: 7666.1
A11: 二 | B11: 措施项目费 | D11: 单价措施项目费+总价措施项目费 | G11: 16257.14
A12: 2.1 | B12: 单价措施项目费 | D12: 人工费+材料费+施工机具使用费
A13: 2.1.1 | B13: 人工费 | D13: 技术措施项目人工费
A14: 2.1.2 | B14: 材料费 | D14: 技术措施项目材料费
A15: 2.1.3 | B15: 施工机具使用费 | D15: 技术措施项目机械费
A16: 2.2 | B16: 总价措施项目费 | D16: 安全文明施工费+其它总价措施项目费 | G16: 16257.14
A17: 2.2.1 | B17: 安全文明施工费 | D17: 人工费+施工机具使用费+人工费+施工机具使用费 | F17: 9.05 | G17: 15167.74
A18: 2.2.2 | B18: 其它总价措施项目费 | D18: 人工费+施工机具使用费+人工费+施工机具使用费 | F18: 0.65 | G18: 1089.4
A19: 三 | B19: 总包服务费
A20: 四 | B20: 企业管理费 | D20: 人工费+施工机具使用费+人工费+施工机具使用费 | F20: 17.5 | G20: 29329.89
A21: 五 | B21: 利润 | D21: 人工费+施工机具使用费+人工费+施工机具使用费 | F21: 14.91 | G21: 24989.07
A22: 六 | B22: 规费 | D22: 人工费+施工机具使用费+人工费+施工机具使用费 | F22: 11.66 | G22: 19542.09
A23: 七 | B23: 索赔与现场签证
A24: 八 | B24: 不含税工程造价 | D24: 分部分项工程费（含5%零星工程）+措施项目费+总包服务费+企业管理费+利润+规费+索赔与现场签证 | G24: 1329298
A25: 九 | B25: 税前包干项目 | D25: 税前包干价
A26: 十 | B26: 税金 | D26: 不含税工程造价+税前包干价 | F26: 3.5411 | G26: 47071.77
A27: 十一 | B27: 税后包干项目 | D27: 税后包干价
A28: 十二 | B28: 设备费 | D28: 设备费
A29: 十三 | B29: 含税工程造价 | D29: 不含税工程造价+税金+税前包干项目+税后包干项目+设备费 | G29: 1376369.8
A31: 2 | B31: 工程造价 | D31: 专业造价总合计 | G31: 1376369.8
A37: 编制人: | C37: 审核人: | E37: 编制日期:

Sheet 水
A2: 单位工程预结算书
A3: 工程名称：2601#给排水工程 | K3: 第 1 页 共 9 页
A4: 序号 | B4: 定额编号 | C4: 子目名称 | D4: 工程量 | G4: 价值（元） | I4: 其中（元） | O4: 工日统计
D5: 单位 | E5: 数量 | G5: 单价 | H5: 合价 | I5: 人工合价 | J5: 材料合价 | L5: 机械合价 | M5: 主材合价 | N5: 设备合价
B6: 010901 | C6: 离心式泵 | H6: 2093.56 | I6: 1446.33 | J6: 387.61 | L6: 259.62 | O6: 17.26
A7: 1 | B7: C1-798 | C7: 潜污泵 安装 | D7: 台 | E7: 2 | G7: 334.84 | H7: 669.68 | I7: 394.94 | J7: 168.12 | L7: 106.62 | O7: 4.714
A8: 2 | B8: C1-801 | C8: 矢量变频给水设备 安装 | D8: 套 | E8: 1 | G8: 1423.88 | H8: 1423.88 | I8: 1051.39 | J8: 219.49 | L8: 153 | O8: 12.546
B9: 080703 | C9: 低压法兰阀门 | H9: 2868.72 | I9: 2210.22 | J9: 336.12 | L9: 322.38 | M9: 73810 | O9: 26.802
A10: 1 | B10: C8-1416 | C10: 低压法兰阀门 公称直径(50mm以内) | D10: 个 | E10: 12 | G10: 34.19 | H10: 410.28 | I10: 278.28 | J10: 61.8 | L10: 70.2 | M10: 5760 | O10: 3.384
B11: 主材 | C11: 铜截止阀 | D11: 个 | E11: 12 | G11: 480 | H11: 5760 | M11: 5760
A12: 2 | B12: C8-1417 | C12: 低压法兰阀门 公称直径(65mm以内) | D12: 个 | E12: 2 | G12: 48.87 | H12: 97.74 | I12: 73.68 | J12: 11.4 | L12: 12.66 | M12: 1100 | O12: 0.894
B13: 主材 | C13: 闸阀 | D13: 个 | E13: 2 | G13: 550 | H13: 1100 | M13: 1100
A14: 3 | B14: C8-1418 | C14: 低压法兰阀门 公称直径(80mm以内) | D14: 个 | E14: 2 | G14: 57.75 | H14: 115.5 | I14: 88.56 | J14: 13.32 | L14: 13.62 | M14: 1300 | O14: 1.074
B15: 主材 | C15: 低压法兰阀门 | D15: 个 | E15: 2 | G15: 650 | H15: 1300 | M15: 1300
A16: 4 | B16: C8-1419 | C16: 低压法兰阀门 公称直径(100mm以内) | D16: 个 | E16: 15 | G16: 74.84 | H16: 1122.6 | I16: 884.85 | J16: 124.8 | L16: 112.95 | M16: 9150 | O16: 10.725
B17: 主材 | C17: 蝶阀 | D17: 个 | E17: 15 | G17: 610 | H17: 9150 | M17: 9150
A18: 5 | B18: C8-1419 | C18: 湿式报警阀组安装 公称直径(100mm以内) | D18: 套 | E18: 2 | G18: 74.84 | H18: 149.68 | I18: 117.98 | J18: 16.64 | L18: 15.06 | M18: 11000 | O18: 1.43
B19: 主材 | C19: 湿式报警阀 | D19: 套 | E19: 2 | G19: 5500 | H19: 11000 | M19: 11000
A20: 6 | B20: C8-1419 | C20: 电触点信号阀 公称直径(100mm以内) | D20: 套 | E20: 13 | G20: 74.84 | H20: 972.92 | I20: 766.87 | J20: 108.16 | L20: 97.89 | M20: 45500 | O20: 9.295
B21: 主材 | C21: 信号阀 | D21: 套 | E21: 13 | G21: 3500 | H21: 45500 | M21: 45500
B22: 090105 | C22: 水流指示器安装 | H22: 4395.95 | I22: 2448.81 | J22: 1907.75 | L22: 39.39 | M22: 14300 | O22: 29.718
A23: 编制人: | F23: 审核人: | K23: 编制日期:
A25: 单位工程预结算书
A26: 工程名称：2601#给排水工程 | K26: 第 2 页 共 9 页
A27: 序号 | B27: 定额编号 | C27: 子目名称 | D27: 工程量 | G27: 价值（元） | I27: 其中（元） | O27: 工日统计
D28: 单位 | E28: 数量 | G28: 单价 | H28: 合价 | I28: 人工合价 | J28: 材料合价 | L28: 机械合价 | M28: 主材合价 | N28: 设备合价
A29: 1 | B29: C9-68 | C29: 水流指示器安装 螺纹连接 公称直径(100mm以内) | D29: 个 | E29: 13 | G29: 338.15 | H29: 4395.95 | I29: 2448.81 | J29: 1907.75 | L29: 39.39 | M29: 14300 | O29: 29.718
B30: 主材 | C30: 水流指示器 | D30: 个 | E30: 13 | G30: 1100 | H30: 14300 | M30: 14300
B31: 090107 | C31: 末端试水装置安装 | H31: 2277.86 | I31: 1590.68 | J31: 650.13 | L31: 37.05 | M31: 79749.6 | O31: 19.318
A32: 1 | B32: C9-80 | C32: 末端试水装置安装 公称直径(32mm以内) | D32: 组 | E32: 2 | G32: 175.22 | H32: 350.44 | I32: 244.72 | J32: 100.02 | L32: 5.7 | M32: 64640 | O32: 2.972
B33: 主材 | C33: 末端试水装置 | D33: 个 | E33: 4.04 | G33: 16000 | H33: 64640 | M33: 64640
A34: 2 | B34: C9-80 | C34: 末端试水装置安装 公称直径(32mm以内) | D34: 组 | E34: 11 | G34: 175.22 | H34: 1927.42 | I34: 1345.96 | J34: 550.11 | L34: 31.35 | M34: 15109.6 | O34: 16.346
B35: 主材 | C35: 末端试水阀 | D35: 个 | E35: 22.22 | G35: 680 | H35: 15109.6 | M35: 15109.6
B36: 090111 | C36: 消防水泵接合器安装 | H36: 1417.12 | I36: 673.2 | J36: 689.56 | L36: 54.36 | M36: 13200 | O36: 8.172
A37: 1 | B37: C9-102 | C37: 消防水泵接合器安装 地下式 DN150 | D37: 套 | E37: 4 | G37: 354.28 | H37: 1417.12 | I37: 673.2 | J37: 689.56 | L37: 54.36 | M37: 13200 | O37: 8.172
B38: 主材 | C38: 消防水泵接合器 | D38: 套 | E38: 4 | G38: 3300 | H38: 13200 | M38: 13200
B39: 090112 | C39: 灭火器具安装 | H39: 3620.94 | I39: 3269.95 | J39: 350.99 | M39: 240000 | O39: 54.502
A40: 1 | B40: C9-108 | C40: 灭火器 放置式 | D40: 10个 | E40: 15 | G40: 83.06 | H40: 1245.9 | I40: 1230.9 | J40: 15 | M40: 45000 | O40: 20.52
B41: 主材 | C41: 手提式磷酸铵盐干粉灭火器 | D41: 套 | E41: 150 | G41: 300 | H41: 45000 | M41: 45000
A42: 2 | B42: C9-111 | C42: 组合式消防柜 安装 | D42: 10个 | E42: 6.5 | G42: 365.39 | H42: 2375.04 | I42: 2039.05 | J42: 335.99 | M42: 195000 | O42: 33.982
...

Sheet 暖费
A2: 单位工程费用汇总表
A3: 工程名称：2601# 暖通工程 | E3: 第 1 页 共 1 页
A4: 序号 | B4: 费用名称 | D4: 取费基数 | F4: 费率 | G4: 费用金额
A5: 1 | B5: 安装工程 | D5: 安装工程 | G5: 2696961.6
A6: 一 | B6: 分部分项工程费（含5%零星工程） | D6: (人工费+材料费+未计价材料费+施工机具使用费)*1.05 | G6: 2341518.5
A7: 1 | B7: 人工费 | D7: 人工费 | G7: 427991.63
A8: 2 | B8: 材料费 | D8: 材料费 | G8: 241775.43
A9: 3 | B9: 未计价材料费 | D9: 主材费 | G9: 1498736.6
A10: 4 | B10: 施工机具使用费 | D10: 机械费 | G10: 61513.95
A11: 二 | B11: 措施项目费 | D11: 单价措施项目费+总价措施项目费 | G11: 47482.04
A12: 2.1 | B12: 单价措施项目费 | D12: 人工费+材料费+施工机具使用费
A13: 2.1.1 | B13: 人工费 | D13: 技术措施项目人工费
A14: 2.1.2 | B14: 材料费 | D14: 技术措施项目材料费
A15: 2.1.3 | B15: 施工机具使用费 | D15: 技术措施项目机械费
A16: 2.2 | B16: 总价措施项目费 | D16: 安全文明施工费+其它总价措施项目费 | G16: 47482.04
A17: 2.2.1 | B17: 安全文明施工费 | D17: 人工费+施工机具使用费+人工费+施工机具使用费 | F17: 9.05 | G17: 44300.25
A18: 2.2.2 | B18: 其它总价措施项目费 | D18: 人工费+施工机具使用费+人工费+施工机具使用费 | F18: 0.65 | G18: 3181.79
A19: 三 | B19: 总包服务费
A20: 四 | B20: 企业管理费 | D20: 人工费+施工机具使用费+人工费+施工机具使用费 | F20: 17.5 | G20: 85663.48
A21: 五 | B21: 利润 | D21: 人工费+施工机具使用费+人工费+施工机具使用费 | F21: 14.91 | G21: 72985.28
A22: 六 | B22: 规费 | D22: 人工费+施工机具使用费+人工费+施工机具使用费 | F22: 11.66 | G22: 57076.35
A23: 七 | B23: 索赔与现场签证
A24: 八 | B24: 不含税工程造价 | D24: 分部分项工程费（含5%零星工程）+措施项目费+总包服务费+企业管理费+利润+规费+索赔与现场签证 | G24: 2604725.6
A25: 九 | B25: 税前包干项目 | D25: 税前包干价
A26: 十 | B26: 税金 | D26: 不含税工程造价+税前包干价 | F26: 3.5411 | G26: 92235.94
A27: 十一 | B27: 税后包干项目 | D27: 税后包干价
A28: 十二 | B28: 设备费 | D28: 设备费
A29: 十三 | B29: 含税工程造价 | D29: 不含税工程造价+税金+税前包干项目+税后包干项目+设备费 | G29: 2696961.6
A31: 2 | B31: 工程造价 | D31: 专业造价总合计 | G31: 2696961.6
A37: 编制人: | C37: 审核人: | E37: 编制日期:

Sheet 暖
A2: 单位工程预结算书
A3: 工程名称：2601# 暖通工程 | K3: 第 1 页 共 6 页
A4: 序号 | B4: 定额编号 | C4: 子目名称 | D4: 工程量 | G4: 价值（元） | I4: 其中（元） | O4: 工日统计
D5: 单位 | E5: 数量 | G5: 单价 | H5: 合价 | I5: 人工合价 | J5: 材料合价 | L5: 机械合价 | M5: 主材合价 | N5: 设备合价
B6: 010801 | C6: 离心式通(引)风机 | H6: 37543.4 | I6: 25583.59 | J6: 8723.48 | L6: 3236.33 | O6: 305.292
A7: 1 | B7: C1-680 | C7: 离心风机箱 安装 | D7: 台 | E7: 6 | G7: 655.83 | H7: 3934.98 | I7: 2519.1 | J7: 1096.02 | L7: 319.86 | O7: 30.06
A8: 2 | B8: C1-682 | C8: 斜流风机 安装 | D8: 台 | E8: 2 | G8: 1120.56 | H8: 2241.12 | I8: 1530.5 | J8: 511.26 | L8: 199.36 | O8: 18.264
A9: 3 | B9: C1-682 | C9: 新风机组 送风风量：1000m3/h 安装 | D9: 台 | E9: 1 | G9: 1120.56 | H9: 1120.56 | I9: 765.25 | J9: 255.63 | L9: 99.68 | O9: 9.132
A10: 4 | B10: C1-683 | C10: 新风机组 送风风量：2000m3/h 安装 | D10: 台 | E10: 1 | G10: 1408.73 | H10: 1408.73 | I10: 975.13 | J10: 296.52 | L10: 137.08 | O10: 11.636
A11: 5 | B11: C1-684 | C11: 全热交换器新风机组 送风风量：2500m3/h 安装 | D11: 台 | E11: 1 | G11: 1810.33 | H11: 1810.33 | I11: 1262.71 | J11: 384.29 | L11: 163.33 | O11: 15.068
A12: 6 | B12: C1-685 | C12: 全热交换器新风机组 送风风量：3000m3/h安装 | D12: 台 | E12: 8 | G12: 2558.14 | H12: 20465.12 | I12: 13863.84 | J12: 4857.28 | L12: 1744 | O12: 165.44
A13: 7 | B13: C1-686 | C13: 全热交换器新风机组 送风风量：3500m3/h 安装 | D13: 台 | E13: 2 | G13: 3281.28 | H13: 6562.56 | I13: 4667.06 | J13: 1322.48 | L13: 573.02 | O13: 55.692
B14: 010802 | C14: 轴流通风机 | H14: 11221.34 | I14: 7724.72 | J14: 2617.2 | L14: 879.42 | O14: 92.179
A15: 1 | B15: C1-692 | C15: 轴流通风机 设备重量(0.2t以内) | D15: 台 | E15: 1 | G15: 455.8 | H15: 455.8 | I15: 262.06 | J15: 140.43 | L15: 53.31 | O15: 3.127
A16: 2 | B16: C1-693 | C16: 轴流通风机 设备重量(0.5t以内) | D16: 台 | E16: 1 | G16: 615.1 | H16: 615.1 | I16: 414.34 | J16: 147.45 | L16: 53.31 | O16: 4.944
A17: 3 | B17: C1-696 | C17: 斜流风机 安装 | D17: 台 | E17: 6 | G17: 1691.74 | H17: 10150.44 | I17: 7048.32 | J17: 2329.32 | L17: 772.8 | O17: 84.108
B18: 010901 | C18: 离心式泵 | H18: 2422.43 | I18: 1611.98 | J18: 543.9 | L18: 266.55 | O18: 19.237
A19: 1 | B19: C1-798 | C19: 补水泵 安装 | D19: 台 | E19: 2 | G19: 334.84 | H19: 669.68 | I19: 394.94 | J19: 168.12 | L19: 106.62 | O19: 4.714
A20: 2 | B20: C1-799 | C20: 循环水泵 安装 | D20: 台 | E20: 3 | G20: 584.25 | H20: 1752.75 | I20: 1217.04 | J20: 375.78 | L20: 159.93 | O20: 14.523
B21: 021702 | C21: 凝聚澄清过滤系统 | H21: 7579.41 | I21: 1160.3 | J21: 5380.4 | L21: 1038.71 | O21: 12.84
A22: 1 | B22: C2-320换 | C22: 软化水箱 外形尺寸：1400X1400X1200 安装 | D22: 台 | E22: 1 | G22: 6601.1 | H22: 6601.1 | I22: 778.06 | J22: 5259.2 | L22: 563.84 | O22: 8.61
A23: 编制人: | F23: 审核人: | K23: 编制日期:
A25: 单位工程预结算书
A26: 工程名称：2601# 暖通工程 | K26: 第 2 页 共 6 页
A27: 序号 | B27: 定额编号 | C27: 子目名称 | D27: 工程量 | G27: 价值（元） | I27: 其中（元） | O27: 工日统计
D28: 单位 | E28: 数量 | G28: 单价 | H28: 合价 | I28: 人工合价 | J28: 材料合价 | L28: 机械合价 | M28: 主材合价 | N28: 设备合价
A29: 2 | B29: C2-343 | C29: 定压罐 安装 | D29: 台 | E29: 1 | G29: 978.31 | H29: 978.31 | I29: 382.24 | J29: 121.2 | L29: 474.87 | O29: 4.23
B30: 022202 | C30: 水处理设备 | H30: 2522.87 | I30: 1351.94 | J30: 544.99 | L30: 625.94 | O30: 16.133
A31: 1 | B31: C2-454 | C31: 软化水处理器 安装 | D31: 台 | E31: 1 | G31: 2522.87 | H31: 2522.87 | I31: 1351.94 | J31: 544.99 | L31: 625.94 | O31: 16.133
B32: 040417 | C32: 风扇 | H32: 883.5 | I32: 756.5 | J32: 127 | M32: 12500 | O32: 8.85
A33: 1 | B33: C4-377 | C33: 换气扇 | D33: 台 | E33: 25 | G33: 35.34 | H33: 883.5 | I33: 756.5 | J33: 127 | M33: 12500 | O33: 8.85
B34: 主材 | C34: 换气扇 | D34: 台 | E34: 25 | G34: 500 | H34: 12500 | M34: 12500
B35: 070104 | C35: 空调器 | H35: 90639.4 | I35: 10420.24 | J35: 80073.56 | L35: 145.6 | O35: 121.532
A36: 1 | B36: C7-46 | C36: 分体空调 安装 | D36: 台 | E36: 3 | G36: 160.78 | H36: 482.34 | I36: 473.34 | J36: 9 | O36: 5.52
A37: 2 | B37: C7-50 | C37: 恒温恒湿空调 安装 | D37: 台 | E37: 1 | G37: 1752.3 | H37: 1752.3 | I37: 1749.3 | J37: 3 | O37: 20.4
A38: 3 | B38: C7-65换 | C38: 热泵机组 安装 | D38: 台 | E38: 4 | G38: 22101.19 | H38: 88404.76 | I38: 8197.6 | J38: 80061.56 | L38: 145.6 | O38: 95.612
B39: 070106 | C39: 风机盘管 | H39: 52254.87 | I39: 27063 | J39: 23096.67 | L39: 2095.2 | O39: 314.28
A40: 1 | B40: C7-74 | C40: 风机盘管安装 吊顶式 | D40: 台 | E40: 291 | G40: 179.57 | H40: 52254.87 | I40: 27063 | J40: 23096.67 | L40: 2095.2 | O40: 314.28
B41: 070201 | C41: 碳钢通风管道 | H41: 191764.8 | I41: 162646.4 | J41: 20915.2 | L41: 8203.2 | M41: 100144 | O41: 1869.44
A42: 1 | B42: C7-99 | C42: 镀锌薄钢板风管 | D42: 10m2 | E42: 160 | G42: 1198.53 | H42: 191764.8 | I42: 162646.4 | J42: 20915.2 | L42: 8203.2 | M42: 100144 | O42: 1869.44
...

Sheet 电费
A2: 单位工程费用汇总表
A3: 工程名称：2601# 电气工程 | E3: 第 1 页 共 1 页
A4: 序号 | B4: 费用名称 | D4: 取费基数 | F4: 费率 | G4: 费用金额
A5: 1 | B5: 安装工程 | D5: 安装工程 | G5: 2749590.7
A6: 一 | B6: 分部分项工程费（含5%零星工程） | D6: (人工费+材料费+未计价材料费+施工机具使用费)*1.05 | G6: 2495945.5
A7: 1 | B7: 人工费 | D7: 人工费 | G7: 263918.57
A8: 2 | B8: 材料费 | D8: 材料费 | G8: 64858.61
A9: 3 | B9: 未计价材料费 | D9: 主材费 | G9: 2015394.9
A10: 4 | B10: 施工机具使用费 | D10: 机械费 | G10: 32918.77
A11: 二 | B11: 措施项目费 | D11: 单价措施项目费+总价措施项目费 | G11: 28793.22
A12: 2.1 | B12: 单价措施项目费 | D12: 人工费+材料费+施工机具使用费
A13: 2.1.1 | B13: 人工费 | D13: 技术措施项目人工费
A14: 2.1.2 | B14: 材料费 | D14: 技术措施项目材料费
A15: 2.1.3 | B15: 施工机具使用费 | D15: 技术措施项目机械费
A16: 2.2 | B16: 总价措施项目费 | D16: 安全文明施工费+其它总价措施项目费 | G16: 28793.22
A17: 2.2.1 | B17: 安全文明施工费 | D17: 人工费+施工机具使用费+人工费+施工机具使用费 | F17: 9.05 | G17: 26863.78
A18: 2.2.2 | B18: 其它总价措施项目费 | D18: 人工费+施工机具使用费+人工费+施工机具使用费 | F18: 0.65 | G18: 1929.44
A19: 三 | B19: 总包服务费
A20: 四 | B20: 企业管理费 | D20: 人工费+施工机具使用费+人工费+施工机具使用费 | F20: 17.5 | G20: 51946.53
A21: 五 | B21: 利润 | D21: 人工费+施工机具使用费+人工费+施工机具使用费 | F21: 14.91 | G21: 44258.45
A22: 六 | B22: 规费 | D22: 人工费+施工机具使用费+人工费+施工机具使用费 | F22: 11.66 | G22: 34611.23
A23: 七 | B23: 索赔与现场签证
A24: 八 | B24: 不含税工程造价 | D24: 分部分项工程费（含5%零星工程）+措施项目费+总包服务费+企业管理费+利润+规费+索赔与现场签证 | G24: 2655554.9
A25: 九 | B25: 税前包干项目 | D25: 税前包干价
A26: 十 | B26: 税金 | D26: 不含税工程造价+税前包干价 | F26: 3.5411 | G26: 94035.85
A27: 十一 | B27: 税后包干项目 | D27: 税后包干价
A28: 十二 | B28: 设备费 | D28: 设备费
A29: 十三 | B29: 含税工程造价 | D29: 不含税工程造价+税金+税前包干项目+税后包干项目+设备费 | G29: 2749590.7
A31: 2 | B31: 工程造价 | D31: 专业造价总合计 | G31: 2749590.7
A37: 编制人: | C37: 审核人: | E37: 编制日期:

Sheet 电
A2: 单位工程预结算书
A3: 工程名称：2601# 电气工程 | K3: 第 1 页 共 7 页
A4: 序号 | B4: 定额编号 | C4: 子目名称 | D4: 工程量 | G4: 价值（元） | I4: 其中（元） | O4: 工日统计
D5: 单位 | E5: 数量 | G5: 单价 | H5: 合价 | I5: 人工合价 | J5: 材料合价 | L5: 机械合价 | M5: 主材合价 | N5: 设备合价
B6: 040102 | C6: 干式变压器安装 | H6: 2513.28 | I6: 1905 | J6: 293.32 | L6: 314.96 | O6: 21.22
A7: 1 | B7: C4-13 | C7: 干式变压器安装 容量(800kV·A以下) | D7: 台 | E7: 2 | G7: 1256.64 | H7: 2513.28 | I7: 1905 | J7: 293.32 | L7: 314.96 | O7: 21.22
B8: 040214 | C8: 高压成套配电柜安装 | H8: 3052.88 | I8: 2433.04 | J8: 207.12 | L8: 412.72 | O8: 27.108
A9: 1 | B9: C4-103 | C9: 高压开关柜 安装 | D9: 台 | E9: 4 | G9: 763.22 | H9: 3052.88 | I9: 2433.04 | J9: 207.12 | L9: 412.72 | O9: 27.108
B10: 040401 | C10: 控制、继电、模拟及配电屏安装 | H10: 4101.3 | I10: 2910.96 | J10: 486.36 | L10: 703.98 | O10: 34.02
A11: 1 | B11: C4-251 | C11: 抽屉式低压配电柜 | D11: 台 | E11: 9 | G11: 455.7 | H11: 4101.3 | I11: 2910.96 | J11: 486.36 | L11: 703.98 | O11: 34.02
B12: 040406 | C12: 成套配电箱安装 | H12: 19072.26 | I12: 15530.94 | J12: 2978.37 | L12: 562.95 | M12: 162000 | O12: 181.44
A13: 1 | B13: C4-277 | C13: 双电源投切箱 安装 | D13: 台 | E13: 25 | G13: 235.46 | H13: 5886.5 | I13: 4793.5 | J13: 919.25 | L13: 173.75 | M13: 50000 | O13: 56
B14: 主材 | C14: 双电源投切箱 | D14: 台 | E14: 25 | G14: 2000 | H14: 50000 | M14: 50000
A15: 2 | B15: C4-277 | C15: 动力配电柜 安装 | D15: 台 | E15: 33 | G15: 235.46 | H15: 7770.18 | I15: 6327.42 | J15: 1213.41 | L15: 229.35 | M15: 66000 | O15: 73.92
B16: 主材 | C16: 动力配电柜 | D16: 台 | E16: 33 | G16: 2000 | H16: 66000 | M16: 66000
A17: 3 | B17: C4-277 | C17: 照明配电箱 安装 | D17: 台 | E17: 13 | G17: 235.46 | H17: 3060.98 | I17: 2492.62 | J17: 478.01 | L17: 90.35 | M17: 26000 | O17: 29.12
B18: 主材 | C18: 照明配电箱 | D18: 台 | E18: 13 | G18: 2000 | H18: 26000 | M18: 26000
A19: 4 | B19: C4-277 | C19: 插座箱 安装 | D19: 台 | E19: 10 | G19: 235.46 | H19: 2354.6 | I19: 1917.4 | J19: 367.7 | L19: 69.5 | M19: 20000 | O19: 22.4
B20: 主材 | C20: 插座箱 | D20: 台 | E20: 10 | G20: 2000 | H20: 20000 | M20: 20000
B21: 040416 | C21: 端子箱 | H21: 1132.74 | I21: 855.12 | J21: 223.44 | L21: 54.18 | M21: 15000 | O21: 9.99
A22: 1 | B22: C4-371 | C22: 端子箱安装 户内 | D22: 台 | E22: 6 | G22: 188.79 | H22: 1132.74 | I22: 855.12 | J22: 223.44 | L22: 54.18 | M22: 15000 | O22: 9.99
B23: 主材 | C23: 接地端子箱 | D23: 台 | E23: 6 | G23: 2500 | H23: 15000 | M23: 15000
B24: 040418 | C24: 照明开关 | H24: 3693.25 | I24: 3407.85 | J24: 285.42 | M24: 49087.5 | O24: 39.811
A25: 1 | B25: C4-382 | C25: 扳式暗开关(单控) 单联 | D25: 10套 | E25: 6 | G25: 66.31 | H25: 397.86 | I25: 369.78 | J25: 28.08 | M25: 3672 | O25: 4.32
A26: 编制人: | F26: 审核人: | K26: 编制日期:
A28: 单位工程预结算书
A29: 工程名称：2601# 电气工程 | K29: 第 2 页 共 7 页
A30: 序号 | B30: 定额编号 | C30: 子目名称 | D30: 工程量 | G30: 价值（元） | I30: 其中（元） | O30: 工日统计
D31: 单位 | E31: 数量 | G31: 单价 | H31: 合价 | I31: 人工合价 | J31: 材料合价 | L31: 机械合价 | M31: 主材合价 | N31: 设备合价
B32: 主材 | C32: 暗装单联单控开关 | D32: 只 | E32: 61.2 | G32: 60 | H32: 3672 | M32: 3672
A33: 2 | B33: C4-382 | C33: 扳式暗开关(单控) 单联 | D33: 10套 | E33: 1 | G33: 66.31 | H33: 66.31 | I33: 61.63 | J33: 4.68 | M33: 612 | O33: 0.72
B34: 主材 | C34: 防水单联开关 | D34: 只 | E34: 10.2 | G34: 60 | H34: 612 | M34: 612
A35: 3 | B35: C4-383 | C35: 扳式暗开关(单控) 双联 | D35: 10套 | E35: 3.5 | G35: 71.12 | H35: 248.92 | I35: 226.49 | J35: 22.44 | M35: 3213 | O35: 2.646
B36: 主材 | C36: 暗装双联单控开关 | D36: 只 | E36: 35.7 | G36: 90 | H36: 3213 | M36: 3213
A37: 4 | B37: C4-383 | C37: 扳式暗开关(单控) 双联 | D37: 10套 | E37: 3.5 | G37: 71.12 | H37: 248.92 | I37: 226.49 | J37: 22.44 | M37: 3213 | O37: 2.646
B38: 主材 | C38: 防水双联开关 | D38: 只 | E38: 35.7 | G38: 90 | H38: 3213 | M38: 3213
A39: 5 | B39: C4-384 | C39: 扳式暗开关(单控) 三联 | D39: 10套 | E39: 12 | G39: 75.95 | H39: 911.4 | I39: 813.6 | J39: 97.8 | M39: 11016 | O39: 9.504
B40: 主材 | C40: 暗装三联单控开关 | D40: 只 | E40: 122.4 | G40: 90 | H40: 11016 | M40: 11016
A41: 6 | B41: C4-397 | C41: 声光控延时开关 | D41: 10套 | E41: 5.5 | G41: 77.44 | H41: 425.92 | I41: 400.18 | J41: 25.74 | M41: 5329.5 | O41: 4.675
B42: 主材 | C42: 声光控开关 | D42: 套 | E42: 56.1 | G42: 95 | H42: 5329.5 | M42: 5329.5
...

Sheet 外电费
A2: 单位工程费用汇总表
A3: 工程名称：室外电气工程 | E3: 第 1 页 共 1 页
A4: 序号 | B4: 费用名称 | D4: 取费基数 | F4: 费率 | G4: 费用金额
A5: 1 | B5: 安装工程 | D5: 安装工程 | G5: 290119.47
A6: 一 | B6: 分部分项工程费（含5%零星工程） | D6: (人工费+材料费+未计价材料费+施工机具使用费)*1.05 | G6: 279212.84
A7: 1 | B7: 人工费 | D7: 人工费 | G7: 1690.79
A8: 2 | B8: 材料费 | D8: 材料费 | G8: 220756.91
A9: 3 | B9: 未计价材料费 | D9: 主材费 | G9: 43329
A10: 4 | B10: 施工机具使用费 | D10: 机械费 | G10: 140.29
A11: 二 | B11: 措施项目费 | D11: 单价措施项目费+总价措施项目费 | G11: 177.61
A12: 2.1 | B12: 单价措施项目费 | D12: 人工费+材料费+施工机具使用费
A13: 2.1.1 | B13: 人工费 | D13: 技术措施项目人工费
A14: 2.1.2 | B14: 材料费 | D14: 技术措施项目材料费
A15: 2.1.3 | B15: 施工机具使用费 | D15: 技术措施项目机械费
A16: 2.2 | B16: 总价措施项目费 | D16: 安全文明施工费+其它总价措施项目费 | G16: 177.61
A17: 2.2.1 | B17: 安全文明施工费 | D17: 人工费+施工机具使用费+人工费+施工机具使用费 | F17: 9.05 | G17: 165.71
A18: 2.2.2 | B18: 其它总价措施项目费 | D18: 人工费+施工机具使用费+人工费+施工机具使用费 | F18: 0.65 | G18: 11.9
A19: 三 | B19: 总包服务费
A20: 四 | B20: 企业管理费 | D20: 人工费+施工机具使用费+人工费+施工机具使用费 | F20: 17.5 | G20: 320.44
A21: 五 | B21: 利润 | D21: 人工费+施工机具使用费+人工费+施工机具使用费 | F21: 14.91 | G21: 273.01
A22: 六 | B22: 规费 | D22: 人工费+施工机具使用费+人工费+施工机具使用费 | F22: 11.66 | G22: 213.5
A23: 七 | B23: 索赔与现场签证
A24: 八 | B24: 不含税工程造价 | D24: 分部分项工程费（含5%零星工程）+措施项目费+总包服务费+企业管理费+利润+规费+索赔与现场签证 | G24: 280197.4
A25: 九 | B25: 税前包干项目 | D25: 税前包干价
A26: 十 | B26: 税金 | D26: 不含税工程造价+税前包干价 | F26: 3.5411 | G26: 9922.07
A27: 十一 | B27: 税后包干项目 | D27: 税后包干价
A28: 十二 | B28: 设备费 | D28: 设备费
A29: 十三 | B29: 含税工程造价 | D29: 不含税工程造价+税金+税前包干项目+税后包干项目+设备费 | G29: 290119.47
A31: 2 | B31: 工程造价 | D31: 专业造价总合计 | G31: 290119.47
A37: 编制人: | C37: 审核人: | E37: 编制日期:

Sheet 外电
A2: 单位工程预结算书
A3: 工程名称：室外电气工程 | K3: 第 1 页 共 1 页
A4: 序号 | B4: 定额编号 | C4: 子目名称 | D4: 工程量 | G4: 价值（元） | I4: 其中（元） | O4: 工日统计
D5: 单位 | E5: 数量 | G5: 单价 | H5: 合价 | I5: 人工合价 | J5: 材料合价 | L5: 机械合价 | M5: 主材合价 | N5: 设备合价
B6: 040801 | C6: 电力电缆敷设 | H6: 2587.99 | I6: 1690.79 | J6: 756.91 | L6: 140.29 | M6: 43329 | O6: 22.308
A7: 1 | B7: C4-721 | C7: 铜芯电力电缆敷设 电缆(截面120mm2以下) | D7: 100m | E7: 2.2 | G7: 1176.36 | H7: 2587.99 | I7: 1690.79 | J7: 756.91 | L7: 140.29 | M7: 43329 | O7: 22.308
B8: 主材 | C8: 电缆 | D8: m | E8: 222.2 | G8: 195 | H8: 43329 | M8: 43329
C9: 补充分部 | H9: 220000 | J9: 220000
A10: 1 | B10: 补子目001 | C10: 电缆沟 | D10: m | E10: 220 | G10: 1000 | H10: 220000 | J10: 220000
A25: 合计 | H25: 265916.99 | I25: 1690.79 | J25: 220756.91 | L25: 140.29 | M25: 43329 | O25: 22.308
A26: 编制人: | F26: 审核人: | K26: 编制日期:

Sheet 外水费
A2: 单位工程费用汇总表
A3: 工程名称：室外给排水工程 | E3: 第 1 页 共 1 页
A4: 序号 | B4: 费用名称 | D4: 取费基数 | F4: 费率 | G4: 费用金额
A5: 1 | B5: 安装工程 | D5: 安装工程 | G5: 354543.05
A6: 一 | B6: 分部分项工程费（含5%零星工程） | D6: (人工费+材料费+未计价材料费+施工机具使用费)*1.05 | G6: 334516.14
A7: 1 | B7: 人工费 | D7: 人工费 | G7: 14286.36
A8: 2 | B8: 材料费 | D8: 材料费 | G8: 146588.69
A9: 3 | B9: 未计价材料费 | D9: 主材费 | G9: 157303
A10: 4 | B10: 施工机具使用费 | D10: 机械费 | G10: 408.75
A11: 二 | B11: 措施项目费 | D11: 单价措施项目费+总价措施项目费 | G11: 1425.43
A12: 2.1 | B12: 单价措施项目费 | D12: 人工费+材料费+施工机具使用费
A13: 2.1.1 | B13: 人工费 | D13: 技术措施项目人工费
A14: 2.1.2 | B14: 材料费 | D14: 技术措施项目材料费
A15: 2.1.3 | B15: 施工机具使用费 | D15: 技术措施项目机械费
